Workbook

Sheet Method
B1: LLMs for software architecture: forward snowballing from the 23 primary studies, with thematic synthesis
B2: Purpose | C2: Records the forward snowballing of the 23 primary studies of the main synthesis (S1-S23) and the thematic analysis of every study it adds. It is kept apart from the main workbook (Final-TA) so that the two evidence bases can be reported separately and merged later. The procedure is the same as in the main synthesis.
B3: Research questions | C3: RQ1 What has been reported to date for the use of LLMs and Gen AI for architectural design support? RQ2 What techniques are reported to optimize and evaluate LLMs and Gen AI for architectural design support? RQ3 What are the emerging trends in the use of LLMs and Gen AI for architectural design? RQ4 How can the approaches, techniques and trends identified in RQ1-RQ3 be extended to support the architecture design of self-adaptive software systems?
B4: Themes and sub-themes | C4: Six themes, revised from the three of the main synthesis following supervisor feedback: RQ1 is answered by T1, RQ2 by T2 and T3, RQ3 by T4, T5 and T6. The sub-themes are those of the main synthesis, regrouped; "benefits and limitations in practice" is split into 1.6 and 5.1. The earlier combined theme "Challenges / Limitations" is split into T5 Limitations (5.1 and 5.2, problems observed in the studies) and T6 Challenges (6.1, formerly 5.3: open problems and future work the authors state); no meaning unit was recoded. T1. LLMs Application / Usage for Architecture Design (RQ1) 1.1 Architecture generation and synthesis from requirements 1.2 Design decision support: pattern, tactic and technology recommendation 1.3 Architecture documentation, decision records and rationale capture 1.4 Architecture analysis, recovery, conformance and smell detection 1.5 The role assigned to the model: assistant, co-designer or autonomous agent 1.6 Reported benefits in practice T2. Techniques for Optimization (RQ2) 2.1 Prompting strategies: chain-of-thought, few-shot, role and self-refinement 2.2 Knowledge grounding: RAG, knowledge graphs and architecture repositories 2.3 Fine-tuning, model adaptation and multi-agent orchestration T3. Techniques for Evaluation (RQ2) 3.1 Evaluation designs: benchmarks, case studies, expert judgement, experiments 3.2 Metrics and quality criteria used to judge generated architectures 3.3 Cost, latency and reproducibility of the reported setups T4. Emerging Trends (RQ3) 4.1 From single-prompt assistance towards agentic and multi-agent architecting 4.2 Integration with model-driven engineering and formal artefact generation 4.3 Human-AI collaboration and the changing role of the architect 4.4 Movement from design-time assistance towards runtime and continuous architecting 4.5 Trust, governance and responsible adoption in industrial settings T5. Limitations (RQ3) 5.1 Reported limitations in practice 5.2 Reported reliability problems: hallucination, inconsistency, non-determinism T6. Challenges (RQ3) 6.1 Open challenges and stated future work
B5: Snowballing procedure | C5: Wohlin (2014), forward direction. The start set is S1-S23. For each seed, the citing records listed by Google Scholar are retrieved and each is logged on the Citing studies sheet with its decision. A record already in the main corpus, or already logged, is recorded as a duplicate on the Citing studies sheet, with the record it duplicates and where that original is (this sheet, or Final-TA for main-corpus studies). For each record we confirm that it cites the seed, then screen on title and abstract and, unless it is clearly excluded, on the full text; the full text decides. A record whose full text cannot be obtained (for example, a Google Scholar citation-only entry) is excluded as not retrievable, with what its record shows. Whether to run further iterations is still to be decided.
B6: Scope criterion | C6: A source is in scope when a model performs, or in a proposal paper is specified to perform, a task whose object is a software architecture. (1) Object of the task: the object of the model's task decides scope; a model acting as a component of an architecture is not doing architectural work. (2) Metadata: title, keywords and venue can support a decision but never decide it. (3) Proposed task: a paper that runs no model is in scope if it specifies a model performing an architectural task. (4) Knowledge artefact: a model producing an ontology, knowledge graph or domain taxonomy is not doing architectural work.
B7: Approach | C7: Thematic synthesis following Cruzes & Dybå (2011), with the six phases of Braun & Clarke (2006) organising the analytic work. Deductive at theme level (the six themes are fixed by the research questions) and inductive below it; a new sub-theme is added only when coded material fits none of the existing ones.
B8: Meaning units and row types | C8: A meaning unit is a short paraphrase from a study carrying one idea, with its section or page. Evidenced: the study reports or does what the sub-theme describes. Coded silence: the study is silent on something the review asks about and the silence matters; the code starts with "Absence:". Related activity: the study does something next to the sub-theme. Only Evidenced rows count as evidence. One unit carries one idea; several instances of the same idea are one unit. Coverage (decided 4 October 2026): unlike the main synthesis, which has a row for every study and sub-theme, a snowballed study has a row only where it addresses the sub-theme or where its silence matters (most often no grounding, no settings, runs or cost, or design-time use only). An empty study/sub-theme pair therefore means that the study does not address the sub-theme and that the silence was not judged analytically relevant; it does not mean the question was not asked.
B9: Trend signal | C9: Every row under T4, and under 6.1, records how the trend is evidenced: Explicit (the authors state it) or No signal. Rows under T1-T3 and T5 carry no signal. A distributional reading of a trend (inferred from the spread of publication years) is a judgement for the synthesis across studies and is not recorded on individual rows (decided 4 October 2026).
B10: Study families | C10: Studies that are not independent (same authors, subjects, data or transcripts) form a family. A snowballed study that belongs to a line of work in the main corpus takes that family's ID (F1-F20); a new line of work gets a new ID (SF1, SF2 ...). Counts of supporting studies are reported with the number of independent families.
B11: RQ4: extension to self-adaptive systems | C11: Answered on StudyWise_SAS_Extension (per study) and SAS extension (per sub-theme). Following supervisor feedback, each is read against MAPE-K, Rainbow and Models@run.time and, where one fits better, another framework (below). Per study: evidence, locus of the architectural work, what breaks for a self-adaptive system (a named property), the framework reading with a link grade, the best fit and why, and a testable extension with preconditions, risks and grounding. Link grades: Direct (the study does it), Partial (it does part of it), Inferred (our mapping), Not applicable. Only Direct and Partial count as evidence from the corpus. A framework not named in a row has nothing to say about it. Frameworks: - MAPE-K feedback loop: Kephart, J.O. & Chess, D.M. (2003). The Vision of Autonomic Computing. Computer, 36(1), 41-50. DOI 10.1109/MC.2003.1160055 - Rainbow (architecture-based self-adaptation): Garlan, D., Cheng, S.-W., Huang, A.-C., Schmerl, B. & Steenkiste, P. (2004). Rainbow: Architecture-Based Self-Adaptation with Reusable Infrastructure. Computer, 37(10), 46-54. DOI 10.1109/MC.2004.175 - Models@run.time: Blair, G., Bencomo, N. & France, R.B. (2009). Models@run.time. Computer, 42(10), 22-27. DOI 10.1109/MC.2009.326 - Three-layer architecture for self-managed systems: Kramer, J. & Magee, J. (2007). Self-Managed Systems: an Architectural Challenge. Future of Software Engineering (FOSE ’07), 259-268. DOI 10.1109/FOSE.2007.19 - FORMS reference model: Weyns, D., Malek, S. & Andersson, J. (2012). FORMS: Unifying Reference Model for Formal Specification of Distributed Self-Adaptive Systems. ACM Transactions on Autonomous and Adaptive Systems, 7(1), 1-61. DOI 10.1145/2168260.2168268 - EUREMA (executable runtime megamodels): Vogel, T. & Giese, H. (2014). Model-Driven Engineering of Self-Adaptive Software with EUREMA. ACM Transactions on Autonomous and Adaptive Systems, 8(4), 1-33. DOI 10.1145/2555612 - ActivFORMS (active formal models): Iftikhar, M.U. & Weyns, D. (2014). ActivFORMS: Active Formal Models for Self-Adaptation. Proceedings of SEAMS 2014, 125-134. DOI 10.1145/2593929.2593944 - Dynamic software product lines: Hallsteinsen, S., Hinchey, M., Park, S. & Schmid, K. (2008). Dynamic Software Product Lines. Computer, 41(4), 93-95. DOI 10.1109/MC.2008.123 - Control-theoretic adaptation: Filieri, A., Maggio, M., et al. (2015). Software Engineering Meets Control Theory. Proceedings of SEAMS 2015, 71-82. DOI 10.1109/SEAMS.2015.12 - Requirements-driven adaptation (awareness requirements): Souza, V.E.S., Lapouchnian, A., Robinson, W.N. & Mylopoulos, J. (2011). Awareness Requirements for Adaptive Systems. Proceedings of SEAMS 2011, 60-69. DOI 10.1145/1988008.1988018
B12: Quality assessment | C12: Same six-item instrument as the main synthesis: Q1 problem definition, Q2 problem context, Q3 research design, Q4 contributions, Q5 insights, Q6 limitations. Each scored 0 (absent), 1 (general or partial) or 2 (explicit), total 0-12. It measures reporting completeness, not methodological soundness. Each score is justified with its location and why the adjacent score was not given. The decision rule is not yet fixed. Scores are the first rater's; the second rater's are pending.
B13: Validation | C13: The supplementary synthesis was initially generated with Claude Opus 5.5 using the shared codebook and researcher-supplied protocol. Authors performed human validation with ChatGPT (GPT-6, High reasoning) as an additional consistency-checking aid. Independent second-rater quality scoring remains pending where not separately documented; source traceability and screening decisions are retained for audit.
B14: References | C14: 1. Cruzes, D.S. & Dybå, T. (2011). Recommended Steps for Thematic Synthesis in Software Engineering. ESEM 2011, 275-284. DOI 10.1109/ESEM.2011.36 2. Braun, V. & Clarke, V. (2006). Using thematic analysis in psychology. Qualitative Research in Psychology, 3(2), 77-101. DOI 10.1191/1478088706qp063oa 3. Wohlin, C. (2014). Guidelines for snowballing in systematic literature studies and a replication in software engineering. EASE 2014, 1-10. DOI 10.1145/2601248.2601268 Framework references are listed under RQ4.

Sheet Seeds
A1: Seed | B1: Authors | C1: Title | D1: Year | E1: Citation source | F1: Records listed | G1: Logged | H1: Included | I1: Excluded | J1: Duplicates | K1: Status
A2: S1 | B2: Maranhão & Guerra | C2: A Prompt Pattern Sequence Approach to Apply Generative AI in Assisting Software Architecture Decision-making | D2: 2024 | E2: Google Scholar | F2: 22 | G2: =COUNTIF(Citing_Studies!$B$2:$B$1000,A2) -> 22 | H2: =COUNTIFS(Citing_Studies!$B$2:$B$1000,A2,Citing_Studies!$G$2:$G$1000,"Included*") -> 7 | I2: =COUNTIFS(Citing_Studies!$B$2:$B$1000,A2,Citing_Studies!$G$2:$G$1000,"Excluded*") -> 12 | J2: =COUNTIFS(Citing_Studies!$B$2:$B$1000,A2,Citing_Studies!$G$2:$G$1000,"Duplicate*") -> 3 | K2: =IF(F2="","Not started",IF(G2=F2,"Complete","To log: "&(F2-G2))) -> Complete
A3: S2 | B3: Maranhão Junior, Melegati & Guerra | C3: Applying a Prompt Pattern Sequence for Decision-Making in Microservices Architectures | D3: 2025 | E3: Google Scholar | F3: 2 | G3: =COUNTIF(Citing_Studies!$B$2:$B$1000,A3) -> 2 | H3: =COUNTIFS(Citing_Studies!$B$2:$B$1000,A3,Citing_Studies!$G$2:$G$1000,"Included*") -> 0 | I3: =COUNTIFS(Citing_Studies!$B$2:$B$1000,A3,Citing_Studies!$G$2:$G$1000,"Excluded*") -> 1 | J3: =COUNTIFS(Citing_Studies!$B$2:$B$1000,A3,Citing_Studies!$G$2:$G$1000,"Duplicate*") -> 1 | K3: =IF(F3="","Not started",IF(G3=F3,"Complete","To log: "&(F3-G3))) -> Complete
A4: S3 | B4: Diaz-Pace, Tommasel, Capilla & Ramírez | C4: Architecture Exploration and Reflection meet LLM-based Agents | D4: 2025 | E4: Google Scholar | F4: 13 | G4: =COUNTIF(Citing_Studies!$B$2:$B$1000,A4) -> 13 | H4: =COUNTIFS(Citing_Studies!$B$2:$B$1000,A4,Citing_Studies!$G$2:$G$1000,"Included*") -> 5 | I4: =COUNTIFS(Citing_Studies!$B$2:$B$1000,A4,Citing_Studies!$G$2:$G$1000,"Excluded*") -> 5 | J4: =COUNTIFS(Citing_Studies!$B$2:$B$1000,A4,Citing_Studies!$G$2:$G$1000,"Duplicate*") -> 3 | K4: =IF(F4="","Not started",IF(G4=F4,"Complete","To log: "&(F4-G4))) -> Complete
A5: S4 | B5: Dhar, Vaidhyanathan & Varma | C5: Can LLMs Generate Architectural Design Decisions? An Exploratory Empirical Study | D5: 2024 | E5: Google Scholar | F5: 119 | G5: =COUNTIF(Citing_Studies!$B$2:$B$1000,A5) -> 119 | H5: =COUNTIFS(Citing_Studies!$B$2:$B$1000,A5,Citing_Studies!$G$2:$G$1000,"Included*") -> 31 | I5: =COUNTIFS(Citing_Studies!$B$2:$B$1000,A5,Citing_Studies!$G$2:$G$1000,"Excluded*") -> 63 | J5: =COUNTIFS(Citing_Studies!$B$2:$B$1000,A5,Citing_Studies!$G$2:$G$1000,"Duplicate*") -> 25 | K5: =IF(F5="","Not started",IF(G5=F5,"Complete","To log: "&(F5-G5))) -> Complete
A6: S5 | B6: Soliman & Keim | C6: Do Large Language Models Contain Software Architectural Knowledge? An Exploratory Case Study with GPT | D6: 2025 | E6: Google Scholar | F6: 31 | G6: =COUNTIF(Citing_Studies!$B$2:$B$1000,A6) -> 31 | H6: =COUNTIFS(Citing_Studies!$B$2:$B$1000,A6,Citing_Studies!$G$2:$G$1000,"Included*") -> 1 | I6: =COUNTIFS(Citing_Studies!$B$2:$B$1000,A6,Citing_Studies!$G$2:$G$1000,"Excluded*") -> 7 | J6: =COUNTIFS(Citing_Studies!$B$2:$B$1000,A6,Citing_Studies!$G$2:$G$1000,"Duplicate*") -> 23 | K6: =IF(F6="","Not started",IF(G6=F6,"Complete","To log: "&(F6-G6))) -> Complete
A7: S6 | B7: Ramachandran | C7: Empowering Software Architects with Artificial Intelligence: Analyzing GitHub Copilot's Role in Modern Architecture Design | D7: 2025 | E7: Google Scholar | F7: 2 | G7: =COUNTIF(Citing_Studies!$B$2:$B$1000,A7) -> 2 | H7: =COUNTIFS(Citing_Studies!$B$2:$B$1000,A7,Citing_Studies!$G$2:$G$1000,"Included*") -> 0 | I7: =COUNTIFS(Citing_Studies!$B$2:$B$1000,A7,Citing_Studies!$G$2:$G$1000,"Excluded*") -> 2 | J7: =COUNTIFS(Citing_Studies!$B$2:$B$1000,A7,Citing_Studies!$G$2:$G$1000,"Duplicate*") -> 0 | K7: =IF(F7="","Not started",IF(G7=F7,"Complete","To log: "&(F7-G7))) -> Complete
A8: S7 | B8: Eisenreich, Speth & Wagner | C8: From Requirements to Architecture: An AI-Based Journey to Semi-Automatically Generate Software Architectures | D8: 2024 | E8: Google Scholar | F8: 56 | G8: =COUNTIF(Citing_Studies!$B$2:$B$1000,A8) -> 56 | H8: =COUNTIFS(Citing_Studies!$B$2:$B$1000,A8,Citing_Studies!$G$2:$G$1000,"Included*") -> 4 | I8: =COUNTIFS(Citing_Studies!$B$2:$B$1000,A8,Citing_Studies!$G$2:$G$1000,"Excluded*") -> 17 | J8: =COUNTIFS(Citing_Studies!$B$2:$B$1000,A8,Citing_Studies!$G$2:$G$1000,"Duplicate*") -> 35 | K8: =IF(F8="","Not started",IF(G8=F8,"Complete","To log: "&(F8-G8))) -> Complete
A9: S8 | B9: Díaz-Pace, Tommasel & Capilla | C9: Helping Novice Architects to Make Quality Design Decisions Using an LLM-Based Assistant | D9: 2024 | E9: Google Scholar | F9: 59 | G9: =COUNTIF(Citing_Studies!$B$2:$B$1000,A9) -> 59 | H9: =COUNTIFS(Citing_Studies!$B$2:$B$1000,A9,Citing_Studies!$G$2:$G$1000,"Included*") -> 4 | I9: =COUNTIFS(Citing_Studies!$B$2:$B$1000,A9,Citing_Studies!$G$2:$G$1000,"Excluded*") -> 15 | J9: =COUNTIFS(Citing_Studies!$B$2:$B$1000,A9,Citing_Studies!$G$2:$G$1000,"Duplicate*") -> 40 | K9: =IF(F9="","Not started",IF(G9=F9,"Complete","To log: "&(F9-G9))) -> Complete
A10: S9 | B10: Dhar, Vaidhyanathan & Varma | C10: Leveraging Generative AI for Architecture Knowledge Management | D10: 2024 | E10: Google Scholar | F10: 24 | G10: =COUNTIF(Citing_Studies!$B$2:$B$1000,A10) -> 24 | H10: =COUNTIFS(Citing_Studies!$B$2:$B$1000,A10,Citing_Studies!$G$2:$G$1000,"Included*") -> 0 | I10: =COUNTIFS(Citing_Studies!$B$2:$B$1000,A10,Citing_Studies!$G$2:$G$1000,"Excluded*") -> 5 | J10: =COUNTIFS(Citing_Studies!$B$2:$B$1000,A10,Citing_Studies!$G$2:$G$1000,"Duplicate*") -> 19 | K10: =IF(F10="","Not started",IF(G10=F10,"Complete","To log: "&(F10-G10))) -> Complete
A11: S10 | B11: Jahić & Sami | C11: State of Practice: LLMs in Software Engineering and Software Architecture | D11: 2024 | E11: Google Scholar | F11: 72 | G11: =COUNTIF(Citing_Studies!$B$2:$B$1000,A11) -> 72 | H11: =COUNTIFS(Citing_Studies!$B$2:$B$1000,A11,Citing_Studies!$G$2:$G$1000,"Included*") -> 4 | I11: =COUNTIFS(Citing_Studies!$B$2:$B$1000,A11,Citing_Studies!$G$2:$G$1000,"Excluded*") -> 33 | J11: =COUNTIFS(Citing_Studies!$B$2:$B$1000,A11,Citing_Studies!$G$2:$G$1000,"Duplicate*") -> 35 | K11: =IF(F11="","Not started",IF(G11=F11,"Complete","To log: "&(F11-G11))) -> Complete
A12: S11 | B12: Ahmad, Waseem, Liang, Fahmideh, Aktar & Mikkonen | C12: Towards Human-Bot Collaborative Software Architecting with ChatGPT | D12: 2023 | E12: Google Scholar | F12: 277 | G12: =COUNTIF(Citing_Studies!$B$2:$B$1000,A12) -> 277 | H12: =COUNTIFS(Citing_Studies!$B$2:$B$1000,A12,Citing_Studies!$G$2:$G$1000,"Included*") -> 11 | I12: =COUNTIFS(Citing_Studies!$B$2:$B$1000,A12,Citing_Studies!$G$2:$G$1000,"Excluded*") -> 227 | J12: =COUNTIFS(Citing_Studies!$B$2:$B$1000,A12,Citing_Studies!$G$2:$G$1000,"Duplicate*") -> 39 | K12: =IF(F12="","Not started",IF(G12=F12,"Complete","To log: "&(F12-G12))) -> Complete
A13: S12 | B13: Keim, Kaplan, Koziolek & Mirakhorli | C13: Does BERT Understand Code?, An Exploratory Study on the Detection of Architectural Tactics in Code | D13: 2020 | E13: Google Scholar | F13: 27 | G13: =COUNTIF(Citing_Studies!$B$2:$B$1000,A13) -> 27 | H13: =COUNTIFS(Citing_Studies!$B$2:$B$1000,A13,Citing_Studies!$G$2:$G$1000,"Included*") -> 0 | I13: =COUNTIFS(Citing_Studies!$B$2:$B$1000,A13,Citing_Studies!$G$2:$G$1000,"Excluded*") -> 23 | J13: =COUNTIFS(Citing_Studies!$B$2:$B$1000,A13,Citing_Studies!$G$2:$G$1000,"Duplicate*") -> 4 | K13: =IF(F13="","Not started",IF(G13=F13,"Complete","To log: "&(F13-G13))) -> Complete
... A24: S23 | B24: Jafari Sarvejahani | C24: Towards Architectural Pen Test Case Generation and Attack Surface Analysis to Support Secure Design | D24: 2025 | E24: Google Scholar | F24: 3 | G24: =COUNTIF(Citing_Studies!$B$2:$B$1000,A24) -> 3 | H24: =COUNTIFS(Citing_Studies!$B$2:$B$1000,A24,Citing_Studies!$G$2:$G$1000,"Included*") -> 0 | I24: =COUNTIFS(Citing_Studies!$B$2:$B$1000,A24,Citing_Studies!$G$2:$G$1000,"Excluded*") -> 3 | J24: =COUNTIFS(Citing_Studies!$B$2:$B$1000,A24,Citing_Studies!$G$2:$G$1000,"Duplicate*") -> 0 | K24: =IF(F24="","Not started",IF(G24=F24,"Complete","To log: "&(F24-G24))) -> Complete
A25: Total | F25: =SUM(F2:F24) -> 781 | G25: =SUM(G2:G24) -> 781 | H25: =SUM(H2:H24) -> 69 | I25: =SUM(I2:I24) -> 477 | J25: =SUM(J2:J24) -> 235

Sheet Citing_Studies
A1: Record | B1: Seed | C1: Authors | D1: Title | E1: Year | F1: Venue | G1: Decision | H1: Ground | I1: Reason | J1: Other seeds cited
A2: S1-F01 | B2: S1 | C2: Narváez, Battaglia, Fernández & Rossi | D2: Designing Microservices Using AI: A Systematic Literature Review | E2: 2025 | F2: Software (MDPI) 4(1), art. 6 | G2: Included as FS01 | I2: Systematic review of 43 studies (2018-2024) on AI in microservices design. Included under our rule for reviews: the model tasks it reports target architecture (service identification and decomposition, decision-making, decision documentation). | J2: S4, S8
A3: S1-F02 | B3: S1 | C3: Abu-Salih, Alotaibi, Alanazi, Abu Khurma, Al-Shboul, Khouri & Aljaafari | D3: Using large language models for semantic interoperability: A systematic literature review | E3: 2025 | F3: ICT Express 11, pp. 819-837 | G3: Excluded | H3: Out of scope (rule 4) | I3: Systematic review of 160 studies on LLMs for semantic interoperability. The model tasks it reports target ontologies, schemas, documents and data, not a software architecture. S1 is cited once, as an example of pattern-based prompting. | J3: None
A4: S1-F03 | B4: S1 | C4: Esposito, Li, Moreschini, Ahmad, Cerny, Vaidhyanathan, Lenarduzzi & Taibi | D4: Generative AI for software architecture. Applications, challenges, and future directions | E4: 2026 | F4: Journal of Systems and Software 231, art. 112607 | G4: Included as FS02 | I4: Multivocal review of 46 sources on generative AI in software architecture. Included under our rule for reviews: its model tasks (decision support, generation, reconstruction, conformance, refactoring) target architecture. S1 is one of its sources. | J4: S3, S4, S5, S7, S8, S9, S10, S11
A5: S1-F04 | B5: S1 | C5: Banitaan, Daoud, Alquran & Akour | D5: Foundation Models in Software Engineering: A Taxonomy, Systematic Review, and In-Depth Analysis of Testing Support | E5: 2026 | F5: Information (MDPI) 17, art. 73 | G5: Excluded | H5: Out of scope (review threshold) | I5: Systematic review of 224 studies across the SE life cycle, with its in-depth analysis on testing. The 12 design/architecture studies are counted in its taxonomy but not synthesised. | J5: None
A6: S1-F05 | B6: S1 | C6: Guimaraes & Nascimento | D6: AI in the Software Development Lifecycle: Insights and Open Research Questions | E6: 2025 | F6: FSE Companion 2025, pp. 1353-1357 | G6: Excluded | H6: Out of scope (rule 3) | I6: Five-page position paper and research roadmap. It runs no model and specifies no architectural model task of its own; its architecture subsection lists other work without synthesis. | J6: S7
A7: S1-F06 | B7: S1 | C7: Zhang, Liu, Sun, Xu, Sun, Li, Jin & Liu | D7: Semantic-Enhanced Automatic Refinement of Architecture Recovery Results Using LLMs | E7: 2026 | F7: ICSE 2026, pp. 1687-1699 | G7: Included as FS03 | I7: Primary study (SemRef): an LLM refines module views recovered from source code, each change checked against dependency structure. The model works on the implemented architecture. | J7: S4, S5, S7, S8
A8: S1-F07 | B8: S1 | C8: Pancher, Melegati & Guerra | D8: Exploratory Test-Driven Development Study with ChatGPT in Different Scenarios | E8: 2025 | F8: XP 2025, LNBIP 545, pp. 145-159 | G8: Excluded | H8: Out of scope (rule 1) | I8: Students used ChatGPT for test-driven development on three programming tasks. The model's task targets unit tests and code, not architecture; S1 is cited only in the background. | J8: S11
A9: S1-F08 | B9: S1 | C9: Alves Pereira, Sousa, Dantas Filho, Albuquerque, Perkusich, Gorgônio & Perkusich | D9: Towards a Characterization of Microservice Architectures Generated by Large Language Models | E9: 2026 | F9: JAWs 2026 (ICSE 2026 workshop); arXiv version read | G9: Included as FS04 | I9: Primary study: LLMs from two providers generate microservice architectures from the documentation of two modular monoliths. Acceptance at JAWs 2026 confirmed on the ICSE 2026 site. | J9: S7, S9
A10: S1-F09 | B10: S1 | C10: Mohamad & Dharam Singh | D10: Prompt Engineering Frameworks and Their Educational Value in Higher Education | E10: 2025 | F10: Innovative Teaching and Learning Journal 9(2), pp. 495-505 | G10: Excluded | H10: Out of scope (review threshold) | I10: Integrative review of five prompt-engineering frameworks for their educational value. S1 is the only architectural study and is summarised as a teaching example, not synthesised. | J10: None
A11: S1-F10 | B11: S1 | C11: Karan, Dhar, Soliman & Vaidhyanathan | D11: Can LLMs Extract Architectural Design Decisions from Source Code Commits? – A Preliminary Exploratory Study | E11: 2026 | F11: IDEA-ARCH 2026 (ECSA 2026 workshop); arXiv version read | G11: Included as FS05 | I11: Primary study: four LLMs extract architectural design decisions from commit messages and diffs. Peer review confirmed on the ECSA 2026 programme; presented 7 Sep 2026, so included after the date window was extended to the retrieval date. | J11: S4, S8, S10
A12: S1-F11 | B12: S1 | C12: Narváez, Battaglia, Fernández & Rossi | D12: Designing Microservices Using AI: A Systematic Literature Review | E12: 2025 | F12: Software (MDPI) 4(1), art. 6 (second listing) | G12: Duplicate of S1-F01 | H12: Duplicate | I12: Same article as S1-F01 (same DOI), listed twice by Google Scholar; the texts were compared and are the same. The original is on this sheet (S1-F01), included and coded as FS01. | J12: As S1-F01
A13: S1-F12 | B13: S1 | C13: Manias, Moulos, Gatzioura, Zdolšek Draksler, Guček & Kyriazis | D13: Architecting Human Oversight in AI-Enabled Software Systems: From Principles to Implementation | E13: 2026 | F13: ICSA 2026 Companion, pp. 127-128 (tutorial abstract) | G13: Excluded | H13: Out of scope (rule 1) | I13: Two-page tutorial abstract on building human oversight into AI-enabled systems. LLMs appear only as system components; no model performs an architectural task. It is also a tutorial abstract, not a research article. | J13: None
A14: S1-F13 | B14: S1 | C14: Copei, Hohlfeld, Kosiol & Ristoski | D14: LLMs Choose the Right Stack: From Patterns to Tools | E14: 2025 | F14: ISE 2025 (ASE 2025 workshop), pp. 276-283 | G14: Included as FS06 | I14: Primary study: six LLMs recommend architectural styles, patterns and tools for four scenarios, directly and through the CAPI decision tree. Workshop uses single-blind review. | J14: S4, S5, S10
A15: S1-F14 | B15: S1 | C15: Mitas & Sachweh | D15: Lifelong Learning in Software Engineering: Towards an AI-driven Tutor for Cloud-Based Software Architectures | E15: 2025 | F15: IEEE E-TEMS 2025, pp. 92-97 | G15: Included as FS07 | I15: Primary study: ChatGPT-4o and Llama 3.1 act as tutors that generate reference architectures from requirements and evaluate students' architectures against them. Six-page full paper, refereed. | J15: S7, S8
A16: S1-F15 | B16: S1 | C16: Zhang, Yiran | D16: Architecture-driven software comprehension across source code and binaries | E16: 2025 | F16: Thesis, Nanyang Technological University (DR-NTU) | G16: Excluded | H16: Not peer reviewed | I16: A thesis, excluded on its record without reading the full text. | J16: Not checked
A17: S1-F16 | B17: S1 | C17: Pancher, Melegati & Guerra | D17: Exploratory Test-Driven Development Study with ChatGPT in Different Scenarios | E17: 2025 | F17: XP 2025, LNBIP 545 (second listing, Google Books) | G17: Duplicate of S1-F07 | H17: Duplicate | I17: Same article as S1-F07 (same DOI), listed twice by Google Scholar; the texts are identical. The original is on this sheet (S1-F07), excluded as out of scope (rule 1). | J17: As S1-F07
A18: S1-F17 | B18: S1 | C18: Rodriguez Sanchez, Vázquez-Santacruz & Cervantes Maceda | D18: A proposal for LLM ensemble learning to achieve consensus in architectural design decisions | E18: 2025 | F18: SSRN preprint 5775315 | G18: Excluded | H18: Not peer reviewed | I18: SSRN preprint, excluded on its record. The full text, received later through S3 (S3-F10), carries the SSRN notice that it has not been peer reviewed on every page and cites S1 in its related work (p. 9). On its content it would be in scope (an ensemble of LLMs generates design decisions guided by ADD); revisit if a peer-reviewed version appears. | J18: S3, S4, S7, S8, S9, S10, S11 (from the full text received as S3-F10)
A19: S1-F18 | B19: S1 | C19: Coelho, Amancio, Paiva Garcia, Vidal Junior, Almeida, Oliveira Leao, Paixao & Freire | D19: More Productive, but at What Cost? Understanding How GenAI Shapes Developers' Work Across the SPACE Dimensions | E19: 2026 | F19: SBES 2026 (CBSoft 2026) | G19: Excluded | H19: Out of scope (rule 1) | I19: Survey of 86 developers on GenAI and productivity (SPACE framework). The activities surveyed are code-level; architecture appears only in one respondent's quote. | J19: None
A20: S1-F19 | B20: S1 | C20: Vardhaman | D20: The Evolution of Cognitive Software Engineering: A Longitudinal Analysis of Large Language Models and Machine Learning in Architectural Synthesis, Fault Prediction, and Code Comprehension | E20: 2024 | F20: The American Journal of Engineering and Technology 6(12), pp. 222-229 | G20: Excluded | H20: Peer review not established | I20: Narrative overview with no method or data. Peer review for this article could not be reliably established, and the main concern is its bibliographic record: it is dated 31 Dec 2024 but cites five papers from ICSA 2025, and the PDF metadata belongs to an unrelated article. Its architecture content would also fail the review threshold. | J20: S7, S10
A21: S1-F20 | B21: S1 | C21: Ribas de Lima & Matos | D21: Prompt Engineering Applied to the Generation of Software Modeling Documents: A Systematic Mapping Study | E21: 2026 | F21: ISE'26 (CBSoft 2026 workshop) | G21: Excluded | H21: Out of scope (review threshold) | I21: Mapping study of 52 studies on prompt engineering for software modelling documents. Architecture and component models (13 of 52) are counted but not synthesised; all findings are pooled across artefact types. Borderline because of the 25% share. | J21: None
A22: S1-F21 | B22: S1 | C22: Jahić | D22: The contextual gap in GenAI for software engineering: Haven't we solved this problem with software architecture? | E22: 2026 | F22: Blog post, Cambridge Advance Online | G22: Excluded | H22: Not peer reviewed | I22: A blog post (15 Jul 2026). The author is the first author of S10. | J22: None
A23: S1-F22 | B23: S1 | C23: Maranhão Junior, Melegati & Guerra | D23: Applying a Prompt Pattern Sequence for Decision-Making in Microservices Architectures | E23: 2025 | F23: ESOCC 2025 (Springer) | G23: Duplicate of S2 | H23: Duplicate (main corpus) | I23: Same study as S2 of the main corpus. The original is in the main workbook (Final-TA, Included studies, S2), where it is included and coded, so it is not screened or coded again here. | J23: Not checked
A24: S2-F01 | B24: S2 | C24: Anghel & Cioara | D24: A systematic review of generative AI usage for IT project management | E24: 2026 | F24: arXiv 2604.21958 (Apr 2026); published in Systems (MDPI) 14(6), art. 722, 22 Jun 2026 (see S2-F02) | G24: Excluded | H24: Out of scope (review threshold) | I24: Systematic review of 30 studies on generative AI in IT project management, organised by PMBOK process group. S2 and S9 are its only architectural studies: each is summarised in the planning section and listed in a table (arXiv pp. 8-9; journal Section 4.2 and Table 2, pp. 10-11), but not synthesised. The authors' own agent vision gives a Technical Lead agent the architectural view in a single sentence, which is not a substantive part either; the journal version calls that section a conceptual perspective beyond the reviewed evidence. The journal version (S2-F02) was read in full and keeps the same treatment. | J24: S9
A25: S2-F02 | B25: S2 | C25: Anghel & Cioara | D25: Generative AI for IT Project Management: A Systematic Review and Future Research Agenda | E25: 2026 | F25: Systems (MDPI) 14(6), art. 722 | G25: Duplicate of S2-F01 | H25: Duplicate | I25: Journal version of the review logged as S2-F01 (its arXiv preprint), listed separately by Google Scholar: same authors, search and 30 studies, with the same text on S2 (Section 4.2, p. 10; Table 2, p. 11). Peer reviewed: received 4 May, revised 18 June, accepted 19 June, published 22 June 2026. The original is on this sheet (S2-F01), excluded under the review threshold; this version was read in full and confirms that decision. | J25: As S2-F01
A26: S3-F01 | B26: S3 | C26: Esposito, Li, Moreschini, Ahmad, Cerny, Vaidhyanathan, Lenarduzzi & Taibi | D26: Generative AI for software architecture. Applications, challenges, and future directions | E26: 2026 | F26: Journal of Systems and Software 231, art. 112607 | G26: Duplicate of S1-F03 | H26: Duplicate | I26: Same article as S1-F03 (same DOI, identical text), reached again through S3, which it reviews as source WL[8] (Section 1, p. 2, and its tables). The original is on this sheet (S1-F03), included and coded as FS02, so it is not screened or coded again. | J26: As S1-F03
A27: S3-F02 | B27: S3 | C27: Meddeb, Batti & Fathallah | D27: BPMN DMN decision table generation based on agentic AI for critical applications | E27: 2026 | F27: Business Process Management Journal (Emerald), online 22 Jan 2026, pp. 1-34 | G27: Excluded | H27: Out of scope (rule 1) | I27: Primary study in which LLM agents (ReAct with retrieval) analyse BPMN process models, extract their decision points and generate DMN decision tables and an optimised process, tested on a supply-chain sales process. The objects of the model's task are a business process and its decision rules, not a software architecture; the architecture described is that of the authors' own agent framework (rule 1). S3 is cited only as an example of ReAct-style reasoning loops (p. 3). | J27: None
A28: S3-F03 | B28: S3 | C28: Cervantes, Kazman & Cai | D28: Better Together: An LLM-assisted approach to designing software architectures using Attribute-Driven Design | E28: 2026 | F28: IEEE Transactions on Software Engineering (early access, 2026); author's version read | G28: Included as FS08 | I28: Primary study: a model with an architect persona follows Attribute-Driven Design to design complete architectures from prioritised drivers, evaluated against a proven solution, by four professional architects and against zero-shot design. Accepted in IEEE TSE (early access). S3 is cited in the related work on design agents (ref. [23], p. 2). | J28: S1 (not in S1's Scholar list), S4, S5, S7, S8, S9, S10
A29: S3-F04 | B29: S3 | C29: Compagnucci, Lu & Trubiani | D29: Agentic Runtime Reconfiguration of Architectural Patterns in Federated Learning | E29: 2026 | F29: Journal of Systems and Software 240, art. 112966 (special issue "AI for SA") | G29: Included as FS09 | I29: Primary study: LLM agents decide after every training round which architectural patterns of a federated-learning system to switch on or off, reasoning over its configuration and metric history, and the system applies the decision. The model is itself a component of the system, but the object of its task is the system's architectural configuration, so it is in scope (rule 1). Peer reviewed (received 2 March, accepted 22 May, online 29 May 2026). S3 is cited in a list of LLM work on architectural decisions (p. 2). | J29: S4, S5, S8, S9
A30: S3-F05 | B30: S3 | C30: Dhar, Vaidhyanathan & Varma | D30: AgenticAKM: Enroute to Agentic Architecture Knowledge Management | E30: 2026 | F30: AGENT 2026 (ICSE 2026 workshop), ACM; arXiv version read | G30: Included as FS10 | I30: Primary study: specialised LLM agents recover architecture knowledge from code repositories and generate Architecture Decision Records, compared with a single prompt in a blind user study on 29 repositories. Accepted at AGENT 2026: listed among the accepted papers on the ICSE 2026 site and presented on 14 April 2026 (lightning talk); the workshop's submission site records 27 of 44 submissions accepted. S3 is cited in the related work on agents in architecture (ref. [15], p. 4). | J30: S4
A31: S3-F06 | B31: S3 | C31: El Outmani, Hatahet, Osterholz, Rausch & Venkataramana Shenoy | D31: Knowledge-Guided Architecture Documentation Recovery with Evidence Grounding and Traceability: A Registered Report (Stage 1) | E31: 2026 | F31: ICSA 2026 Companion (IEEE), pp. 534-541 | G31: Included as FS11 | I31: Stage-1 registered report, a preregistered study design without results: an LLM multi-agent pipeline is specified to recover evidence-grounded architecture documentation (a C4-level component view with traceability links) from repositories under four levels of injected architectural knowledge. In scope under rule 3 (a model is specified to perform an architectural task). Published in the ICSA 2026 Companion proceedings (IEEE, pp. 534-541; Crossref); the track is not named on the paper or found in the conference programme, but it is an eight-page research paper, not an abstract, and a Stage-1 report is reviewed before acceptance. S3 is cited in the related work on agentic systems (ref. [25], p. 536). | J31: S4, S5, S14 (via its arXiv version)
A32: S3-F07 | B32: S3 | C32: Zimmermann & Seiger | D32: AI Assistance for Architectural Decision Making: Domain-Driven Context and Prompt Engineering | E32: 2026 | F32: IDEA-ARCH 2026 (ECSA 2026 workshop), short paper; author version read | G32: Included as FS12 | I32: Short vision paper: from practitioner input and action research it distils eight uses of generative and agentic AI in architectural decision making, proposes decision-assistance tooling that injects modelled project knowledge into prompt templates, and illustrates it with an ADR-review prompt run with several LLMs. Accepted at IDEA-ARCH 2026, like FS05: listed in the ECSA 2026 programme (presented 7 September 2026), and each submission is reviewed by at least three programme committee members. S3 is cited for the option-exploration use case (ref. [9], pp. 3-4). | J32: S4, S11
A33: S3-F08 | B33: S3 | C33: Korvic | D33: Machine Learning and Large Language Model Approaches for Software Code Understanding, Prediction, and Architectural Decision Support | E33: 2024 | F33: Frontiers in Emerging Multidisciplinary Sciences 1(1), pp. 25-34 (irjernet.com); dated 31 Dec 2024, header reads 2026 | G33: Excluded | H33: Out of scope (review threshold) | I33: Narrative overview that draws only on existing literature, mostly machine learning for code (defect prediction, code representation, summarisation). We accept it as peer reviewed; the journal site could not be reached to check the process independently. Its architecture content is five papers (S3, S4, S8, S9 and Arun et al., 2025), each summarised in one or two sentences and repeated across the methodology, results and discussion, without comparison or synthesis, so it falls below the review threshold, as S1-F09 and S2-F01 did. Its bibliographic record is inconsistent: it is dated to volume 1, issue 1, published 31 December 2024, yet its header reads FEMS (2026), the PDF was created in March 2026, and it cites two papers from 2025; six of its 26 references are never cited in the text. S3 is cited as an example of agents for architecture exploration (p. 29). | J33: S4, S8, S9
A34: S3-F09 | B34: S3 | C34: Maia, Bandeira, Oliveira, Mendes & Mendonca | D34: LLM-Native Applications as a Paradigm for AI-Driven Software Architecture: Taxonomy, Application Families, and Architecting Practices | E34: 2026 | F34: SSRN preprint 6799068 (manuscript in the JSS template) | G34: Excluded | H34: Not peer reviewed | I34: SSRN preprint; every page states that it has not been peer reviewed. It extends the authors' ICSE 2026 poster on LLM-native applications. It would also be out of scope under rule 1: it proposes a taxonomy, application families and a conceptual architecture for applications whose runtime behaviour is orchestrated by an LLM, with an example chatbot for literature reviews (SCRIBE), so the model is a component of the system and performs no task on a software architecture; a peer-reviewed version would therefore still be excluded. S3 is cited as an example of agentic AI (p. 3). | J34: S10
A35: S3-F10 | B35: S3 | C35: Rodriguez Sanchez, Vázquez-Santacruz & Cervantes Maceda | D35: A proposal for LLM ensemble learning to achieve consensus in architectural design decisions | E35: 2025 | F35: SSRN preprint 5775315 | G35: Duplicate of S1-F17 | H35: Duplicate | I35: Same SSRN preprint as S1-F17 (abstract 5775315), reached again through S3, which it cites in its related work (p. 9). The original is on this sheet (S1-F17), excluded as not peer reviewed; this full text carries the SSRN notice on every page and confirms that decision. | J35: As S1-F17
A36: S3-F11 | B36: S3 | C36: Compagnucci, Lu & Trubiani | D36: Agentic Runtime Reconfiguration of Architectural Patterns in Federated Learning | E36: 2026 | F36: Journal of Systems and Software 240, art. 112966 (second listing) | G36: Duplicate of S3-F04 | H36: Duplicate | I36: Same article as S3-F04 (same DOI), listed twice by Google Scholar; the two PDFs differ only in file metadata, and their texts are identical. The original is on this sheet (S3-F04), included and coded as FS09. | J36: As S3-F04
A37: S3-F12 | B37: S3 | C37: Miccio Palermo | D37: Agentes basados en LLMs para la derivación de tareas de desarrollo backend a partir de requerimientos textuales | E37: 2026 | F37: CIbSE 2026 (XXIX Congresso Ibero-Americano em Engenharia de Software), Doctoral Symposium (Simpósio de Doutorado), SBC SOL; DOI 10.5753/cibse.2026.42459; published 11 May 2026 (from the SOL page seen through S8-F59); the file read states no venue (8 pages; ISISTAN, CONICET-UNICEN, Argentina) | G37: Excluded | H37: Not in English | I37: Written in Spanish, with an English abstract. It is structured as a research proposal (research questions, objectives, preliminary progress, future work) for a multi-agent LLM workflow that refines requirements, proposes service and component boundaries, defines API contracts and specifies tests for backend development. On its content it would be a candidate for scope; revisit if an English, peer-reviewed version appears. S3 is cited as an example of agents that combine LLMs with planning, reflection and search (ReArch, p. 4). | J37: S4, S8, S11
A38: S3-F13 | B38: S3 | C38: Plokha, V. | D38: Arkitektonisk kontroll i LLM-baserade AI-agenter | E38: 2026 | F38: Not stated (Google Scholar citation-only entry) | G38: Excluded | H38: Not retrievable | I38: Google Scholar lists it only as a [CITATION] entry, with no link to a document (screenshot of the entry kept), and a web search found no copy. The Swedish title ('Architectural control in LLM-based AI agents') suggests that it is not written in English, and no venue is given. Whether and where it cites S3 could not be checked beyond Google Scholar's listing. | J38: Not checked
A39: S4-F01 | B39: S4 | C39: Li, Zhao, Jiang et al. (19 authors) | D39: Large Language Models for manufacturing | E39: 2026 | F39: Journal of Manufacturing Systems 86, pp. 516-545 (review) | G39: Excluded | H39: Out of scope (rule 1) | I39: Review of LLM applications across the manufacturing lifecycle (CAD and CAM, product, chip and aerospace design, supply chains, quality control, education, patents), with some evaluations of GPT-4V. The objects of the model tasks it reports are manufacturing products, processes and documents, not a software architecture, and it synthesises no architectural model task, so it could not meet the review threshold either. S4 is cited once, with two other works, for the claim that AI may turn designers into orchestrators of AI-assisted design (ref. [66], p. 520). | J39: None
A40: S4-F02 | B40: S4 | C40: Ye, Zhang, Ma et al. (29 authors) | D40: LLMs4All: A Review of Large Language Models Across Academic Disciplines | E40: 2025 | F40: arXiv preprint 2509.19580 (v5, Nov 2025; also on Preprints.org) | G40: Excluded | H40: Not peer reviewed | I40: arXiv preprint (v5, 23 Nov 2025), also posted on Preprints.org; no peer-reviewed version was found. It reviews LLM use across academic disciplines, from the arts, letters and law to business, science and engineering. Its only software-architecture content is S4 and the DRAFT preprint by the S4 authors and two others, and both are filed under building architecture (§3.4 Arts and Architecture): S4 gets a few sentences in §3.4.5 and is listed again as the benchmark 'AKM' in §3.4.6 and Table 12, and DRAFT gets a paragraph and a Table 12 row. It would therefore also fail the review threshold. S4 is cited as ref. [283] in Table 11 (p. 45), §3.4.5 (p. 48) and §3.4.6 with Table 12 (pp. 48-49). | J40: None
...

Sheet Included_Studies
A1: Sr | B1: ID | C1: Found via | D1: Authors | E1: Title | F1: Year | G1: Venue | H1: Contribution type | I1: LLM / Gen AI used | J1: Architectural task addressed | K1: Evaluation type | L1: Family | M1: Coverage and independence
A2: 1 | B2: FS01 | C2: S1-F01, S1-F11, S4-F09, S4-F73, S8-F01, S8-F36; cites S1, S4, S8 | D2: Narváez, Battaglia, Fernández & Rossi | E2: Designing Microservices Using AI: A Systematic Literature Review | F2: 2025 | G2: Software (MDPI), vol. 4, article 6; DOI 10.3390/software4010006 | H2: Secondary study: systematic literature review following PRISMA, 43 studies published 2018-2024 on AI techniques in microservices design. Five research questions: techniques used, challenges, benefits, emerging trends, and the artefacts used as input. | I2: None run. The reviewed studies use machine learning (53.5%; clustering such as k-Means and word embeddings), NLP (32.6%), BERT-based models, deep and reinforcement learning and LSTM networks. Language models and generative AI appear as an emerging trend, supported by a few cited works (refs. [27], [38]-[41]). | J2: Microservice design: service identification from requirements in greenfield projects, decomposition of existing monoliths, architectural decision-making and decision documentation. Runtime autoscaling, fault tolerance and monitoring are also covered, which the authors include for completeness. | K2: Systematic literature review: IEEE Xplore, ACM Digital Library and Google Scholar; 2018-2024; 97 full texts read (20 more not accessible), 43 included; screening by two authors; no formal quality assessment of the included studies. | L2: SF1 | M2: 28 meaning units (7 / 4 / 4 / 6 / 5 / 2 across T1-T6). Secondary study (systematic review). New family SF1 (UAI and LIFIA, Argentina). It reports on S1, S4 and S8, so its units about them are not independent evidence; its content on language models is thin and rests on single citations.
A3: 2 | B3: FS02 | C3: S1-F03, S3-F01, S4-F03, S5-F02, S7-F01, S8-F03, S9-F01, S10-F02, S11-F11; cites S1, S3, S4, S5, S7, S8, S9, S10, S11 | D3: Esposito, Li, Moreschini, Ahmad, Cerny, Vaidhyanathan, Lenarduzzi & Taibi | E3: Generative AI for software architecture. Applications, challenges, and future directions | F3: 2026 | G3: The Journal of Systems and Software, vol. 231, article 112607 (online 17 Sep 2025); DOI 10.1016/j.jss.2025.112607 | H3: Secondary study: multivocal literature review of 36 peer-reviewed and 10 grey sources (search February 2025) on generative AI in software architecture. Research questions on purposes, models and techniques (RQ1), life-cycle phases, architectural styles, quality tasks, validation methods and use cases (RQ2), and challenges (RQ3); themes extracted by open coding. | I3: None run. Reports model use across its sources: OpenAI GPT models 62% of the model uses counted in Table 12, Google models 9%, LLaMA 8%, with DeepSeek and Qwen appearing in 2024-2025; cloud-hosted models preferred over on-premises ones. | J3: As reported across its sources: architectural decision support (38%), reverse engineering and reconstruction (19%), architecture generation (19%), quality assessment (9%), comprehension, requirements, migration and traceability. Life-cycle transitions: requirements to architecture 40%, architecture to code 32%, code to architecture 13%, requirements to architecture to code 12%, architecture to architecture 3%. | K3: Multivocal literature review following Garousi et al.: four digital libraries and five search engines, 1053 unique records screened to 46; two authors per decision with a third for disagreements and Cohen’s kappa reported; snowballing; quality assessment (Dybå and Dingsøyr checklist for peer-reviewed sources, Garousi criteria for grey); replication package on Zenodo. | L3: SF2 | M3: 34 meaning units (8 / 4 / 6 / 8 / 4 / 4 across T1-T6). Secondary study (multivocal review). New family SF2 (Oulu with Tampere, Arizona and IIIT Hyderabad); Vaidhyanathan co-authored S4 and S9 (F3), but this is a review, so it is kept separate. It reports on nine seeds (S1, S3-S5, S7-S11). Reliability: three statements about S1 conflict with our coding of S1; the snowballing yield and sources searched are reported inconsistently; three grey sources are cited but not listed.
A4: 3 | B4: FS03 | C4: S1-F06, S4-F41, S5-F10, S7-F17, S8-F21; cites S1, S4, S5, S7, S8 | D4: Zhang, Liu, Sun, Xu, Sun, Li, Jin & Liu | E4: Semantic-Enhanced Automatic Refinement of Architecture Recovery Results Using LLMs | F4: 2026 | G4: ICSE ’26, pp. 1687-1699; DOI 10.1145/3744916.3773114 | H4: Technique with quantitative evaluation. SemRef refines the output of existing architecture recovery tools by combining dependency analysis with a language model’s semantic judgement, in four stages: resizing modules (split and merge), file-level regrouping, hierarchy construction and iterative top-down refinement with module summaries. | I4: GPT-4o-mini (gpt-4o-mini-2024-07-18) by default, temperature 0, seed 1. Compared with GPT-4o (2024-08-06), Gemini-2.0-flash-001, Llama 3.3 (70B) and DeepSeek-V3-0324. All off the shelf; no fine-tuning. | J4: Architecture recovery, module view: correcting the file-to-module grouping recovered from source code and turning it into a named module hierarchy with a summary per module. The direction is from code to architecture. | K4: Quantitative evaluation on 9 open-source projects with published ground-truth architectures (25.7K to 11.7M lines), 10 recovery-tool implementations giving 90 inputs, five similarity metrics plus reduction in distance to perfect, ANOVA across tools and projects, an ablation of the five stages, token-cost analysis, a comparison of five models, and a case study on Bash. | L4: SF3 | M4: 37 meaning units (9 / 7 / 8 / 5 / 5 / 3 across T1-T6). Primary study. New family SF3 (Nanyang Technological University with Imperial, HUST and Xi'an Jiaotong). The recommended input tool, SARIF, is the authors' own earlier work. FS17 (SemArc) belongs to the same family. Reliability: the abstract says 'trillions of lines of code' (largest project 11.7M); text figures in Section 4.2.1 differ from Table 3, and units use the table values.
A5: 4 | B5: FS04 | C5: S1-F08, S7-F25, S9-F17; cites S1, S7, S9 | D5: Alves Pereira, Sousa, Dantas Filho, Albuquerque, Perkusich, Gorgônio & Perkusich | E5: Towards a Characterization of Microservice Architectures Generated by Large Language Models | F5: 2026 | G5: JAWs 2026, Journal Ahead Workshop at ICSE 2026 (13-14 April 2026); version read: arXiv:2609.20308v1 | H5: Exploratory empirical study. Characterises, rather than judges, the microservice architectures language models produce when asked to decompose a modular monolith from its textual architecture documentation, adapting the M2MDF decomposition framework so that model inference replaces clustering. Framed as a baseline for a research agenda on architecture-to-architecture transformation. | I5: "GPT-based models from OpenAI" and "models from DeepSeek"; no model name, version, temperature or other setting is reported. Zero-shot and few-shot prompting. No fine-tuning. | J5: Architecture-to-architecture transformation: deriving a microservice architecture (service boundaries, responsibilities, communications) from the architecture documentation of an existing modular monolith, for early-stage modernisation. | K5: Two systems (MediaStore, TeaStore), two providers, two prompting strategies, one run per configuration. No ground truth; outputs in CSV are characterised by eight structural and textual metrics (service count, communications, density, isolated services, responsibility length, vocabulary, redundancy). | L5: SF4 | M5: 25 meaning units (6 / 4 / 5 / 3 / 4 / 3 across T1-T6). Primary study. New family SF4 (VIRTUS, Federal University of Campina Grande); extends the authors' SBCARS 2025 study. arXiv version of the JAWs 2026 paper read. Its inputs are the documentation prepared in Fuchs et al. (ICSA 2025, FS15), the predecessor of S20. Cites FS02.
A6: 5 | B6: FS05 | C6: S1-F10, S4-F71, S4-F108, S10-F52, S10-F69; cites S1, S4, S8, S10 | D6: Karan, Dhar, Soliman & Vaidhyanathan | E6: Can LLMs Extract Architectural Design Decisions from Source Code Commits? – A Preliminary Exploratory Study | F6: 2026 | G6: IDEA-ARCH 2026, Intelligent & Data-driven Engineering for Software Architecture workshop at ECSA 2026 (Bolzano), full paper, presented 7 Sep 2026; published in ECSA 2026, LNCS 16991, pp. 208-215 (Springer, 2027), DOI 10.1007/978-3-032-39143-8_19; arXiv:2609.03721v1 read and checked against the published chapter (S4-F108) | H6: Exploratory empirical study (eight-page workshop paper). Tests whether language models can recover architectural design decisions from source code commits alone, comparing zero-shot and few-shot prompting across four models. | I6: Gemini 3 Pro (parameters not disclosed), DeepSeek R1 (685B), Kimi K2 Thinking (1T, 32B active), Qwen3 (32B), chosen from the Arena leaderboard. Zero-shot prompting, and few-shot prompting with examples retrieved by embedding similarity. No fine-tuning. Temperature, runs, embedding model and number of examples not reported. | J6: Architectural knowledge recovery: extracting the architectural design decision behind a single commit from its message and git diff, for architectural knowledge management. | K6: 30 developer-written decisions from Apache Cassandra, Hadoop and Tajo (Maestro dataset, linked to commits by Jira ID); four models by two prompting strategies. Automated comparison with the documented decision (ROUGE-L, BLEU, METEOR, BERTScore) and single-author inspection of the 60 Gemini outputs on a rubric fixed in advance (abstraction level, verbosity, rationale). | L6: F3 | M6: 26 meaning units (6 / 4 / 6 / 2 / 5 / 3 across T1-T6). Primary study. Family F3 with S4 and S9 (shared authors Dhar and Vaidhyanathan; continues S4's work on design decisions), overlapping F4 through Soliman; not independent of S4. arXiv version of the IDEA-ARCH 2026 paper read. The published chapter (ECSA 2026, LNCS 16991, pp. 208-215, Springer, dated 2027) was reached through S4 (S4-F108), and its text matches the arXiv version apart from typesetting.
A7: 6 | B7: FS06 | C7: S1-F13, S4-F83, S5-F24, S10-F58; cites S1, S4, S5, S10 | D7: Copei, Hohlfeld, Kosiol & Ristoski | E7: LLMs Choose the Right Stack: From Patterns to Tools | F7: 2025 | G7: ISE 2025, International Workshop on Intelligent Software Engineering at ASE 2025 (Seoul, 16 Nov 2025); ASE 2025 Workshops proceedings (IEEE), pp. 276-283; DOI 10.1109/ASEW67777.2025.00057 | H7: Empirical evaluation in three experiments of off-the-shelf models on architectural pattern recommendation: direct prompting (naive and improved prompts), decision-tree-guided recommendation through the authors’ CAPI method, and mapping patterns to implementation tools. | I7: Six models through the GWDG Chat AI service: ChatGPT-4o (closed; "ChatGPT-o4" in the text), DeepSeek-R1, Meta-Llama-3.1-8B-Instruct, Mistral-Large-Instruct, Codestral-22B, Qwen2.5-VL-72B-Instruct; temperature 0.5, top-p 0.5. Naive and improved prompts, decision-tree-guided prompting, JSON-structured output. No fine-tuning. | J7: Design decision support: choosing an architectural style (monolithic, client-server, microservices) and recommending architectural patterns for a described system, then mapping the patterns to implementation tools chosen from a supplied list (CNCF Landscape). | K7: Four scenarios from the authors’ CAPI user study. Exp. 1: 480 prompts (6 models, 2 prompts, 4 scenarios, 10 runs) rated on three-point ordinal scales (reasonable, variance, patterns). Exp. 2: one CAPI traversal per model and scenario, compared with 10 human participants by number of patterns and a penalty-based distance to the authors’ must/could/must-not lists. Exp. 3: JSON compliance and reasonableness of the tools. | L7: SF5 | M7: 23 meaning units (4 / 4 / 6 / 2 / 5 / 2 across T1-T6). Primary study. New family SF5 (Kassel, Fraunhofer IEE, Marburg); builds on the authors' own CAPI method. Scenarios, reference lists and human comparison data come from the authors' earlier CAPI study, so the benchmark is not independent of the method.
A8: 7 | B8: FS07 | C8: S1-F14, S7-F45, S8-F48; cites S1, S7, S8 | D8: Mitas & Sachweh | E8: Lifelong Learning in Software Engineering: Towards an AI-driven Tutor for Cloud-Based Software Architectures | F8: 2025 | G8: E-TEMS 2025, IEEE European Technology and Engineering Management Summit (Bruges, 26-28 May 2025), pp. 92-97; DOI 10.1109/E-TEMS64751.2025.11239087 | H8: Method proposal with an exploratory test: a four-step prompting method that makes a language model act as a tutor for novice architects, tried out with simulated student questions on one dataset. | I8: ChatGPT-4o (cloud) and Llama 3.1 Tulu 3 70B (AllenAI community model, run locally). Role prompting in four steps, with a relevance check and a self-check against the role instructions. No model fine-tuning ("fine-tune the prompts" in the paper means revising the prompts). | J8: Generating several reference architectures with decision records from requirements, and evaluating students’ architectures (component diagrams, a domain model) and requirement summaries against them, as a tutor for novice architects. | K8: Exploratory test on the MobSTr dataset (requirements, assumptions, hazards and a component diagram of an automotive driver assistance system): the authors send example student questions to both models and report their behaviour qualitatively. No students, metrics, number of questions or runs reported. | L8: SF6 | M8: 20 meaning units (6 / 4 / 5 / 1 / 3 / 1 across T1-T6). Primary study, exploratory. New family SF6 (IDiAL, Dortmund University of Applied Sciences and Arts). Evidence is the authors' qualitative observation; the test case is an automotive embedded system despite the 'cloud-based' title. A domain model produced with S7's approach is one of its inputs.
