Workbook

Sheet Method_Used
B1: LLMs for software architecture, thematic synthesis of 23 primary studies
B2: Research Questions (RQs) | C2: RQ1 What has been reported to date for the use of LLMs and Gen AI for architectural design support? RQ2 What techniques are reported to optimize and evaluate LLMs and Gen AI for architectural design support? RQ3 What are the emerging trends in the use of LLMs and Gen AI for architectural design? RQ4 How can the approaches, techniques and trends identified in RQ1-RQ3 be extended to support the architecture design of self-adaptive software systems?
B3: Approach Used | C3: Thematic synthesis of primary research is performed, using the suggested process of Cruzes and Dyb are (2011) thematic synthesis in software engineering: extract data, code the extracted data, translate the codes into themes, develop a model of higher level themes, and evaluate the credibility of the synthesis. The analytic work is organized into the steps in the six-phase structure of Braun and Clarke (2006). The analysis is deductive at the level of theme and inductive at the lower levels. The themes were not discovered and were predetermined in terms of content, thus the structure of the themes is not an option and finding. Three passes (one per descriptive research question) were used in the first pass; the study has six passes (T1 answers RQ1, T2 and T3 answer RQ2, T4, T5 and T6 answer RQ3). Both are deductive on level of themes; the mapping of its themes and sub-themes are discussed in Themes and sub-themes. The data were structured into codes and sub-themes: a code book was created based on a two-study pilot, which was then applied to all other studies, new codes were created and old ones were merged as the corpus was processed, and the sub-themes were then formed by clustering codes instead of defining them at the start. This is a code-book methodology in the three-way typology of thematic analysis established by Braun and Clarke (2021): a structured code book and themes determined early, used by more than a single coder but without measuring inter-coder agreement which is a characteristic of coding-reliability thematic analysis. It is referred to as Braun & Clarke (2006) as having a six-phase sequence, which is merely an organising structure of the analytic work, which that paper is authorized to permit in theoretical and deductive discussions and critique. Under 'Validation' how the code book was implemented and how conflict was solved is documented.
B4: Coding Ladder | C4: The analytic ladder is displayed in each row of the 'Thematic map' sheet. Left-right reading: It progresses in the order of concrete to abstract: Meaning unit, Code, Sub-theme, Theme. Each Theme unreading into right to left sets out its Sub-themes, in which the Codes, founded on the original Meaning units, are found. The two directions are internally consistent, an audit trail in a data-themes and vice versa.
B5: Meaning Unit | C5: A concise, summary description of a primary study containing single idea, an outlined method, methodology, discovery or reported constraint. Both paraphrased and not quoted, in order to both not reproduce licenced copyrighted text, but to place the units, more or less, on equal footing, with respect to granularity. Section or page is noted in a manner that all the units can be traced.
B6: Coding Absences | C6: A study that is silent on an aspect on which the review inquires, and where that silence is analytically significant, is coded as a unit of meaning with the word Absence at the beginning of the code, and the Source column names where such a piece of information would have been found. Absences are reported individually of positive findings and are never stated as a claim that the authors made.
B7: Granularity Rule | C7: Each unit of meaning has one idea. Where a study gives many instances of the same idea given only one is literally counted, and the multiplicity is indicated in it, instead of a series of similar epochs, when a long paper will weigh against a short, that being on a lengthy scale.
B8: Study Families and Independence | C8: The result of some of the studies in the corpus is not independent: one of the authors might report a method in one place and its evaluation in another, with the same subjects, the same companies and even the same transcripts of the model. These kinds of studies compose a family. The sheet included studies records the family in a specific column. To communicate the number of studies supporting a theme, indicate the number of independent families with that number, and state the total number research studies, otherwise a one-line of work is reported twice and evidence appears more extensive than it is. On that test, three families are created. S1 and S2 are F1; same first author, same two companies and the URLs published on S2 in two prompt-transcripts are character by character identical to the URLs published on S1. For instance; S3 and S8 are F2: S3 states ArchMind, we proposed the ArchMind research prototype in earlier work [8], and S8 is the paper on ArchMind. S4 and S9 Are F3: the study S4 reports in full that S9 reports is not a related report, but an overlapping report.
B9: Theme or Sub-theme | C9: Related codes are clustered by sub-themes; themes are the broad structure which will respond to the research question or a single facet of it. Design applies six themes with T1 answering RQ1, T2 and T3 answering RQ2 and T4, T5 and T6 answering RQ3. Six themes: RQ1 is answered by T1, RQ2 by T2 and T3, RQ3 by T4, T5 and T6 with 20 sub-themes. T1. LLMs Application / Usage for Architecture Design (RQ1) 1.1 Architecture generation and synthesis from requirements 1.2 Design decision support: pattern, tactic and technology recommendation 1.3 Architecture documentation, decision records and rationale capture 1.4 Architecture analysis, recovery, conformance and smell detection 1.5 The role assigned to the model: assistant, co-designer or autonomous agent 1.6 Reported benefits in practice T2. Techniques for Optimization (RQ2) 2.1 Prompting strategies: chain-of-thought, few-shot, role and self-refinement 2.2 Knowledge grounding: RAG, knowledge graphs and architecture repositories 2.3 Fine-tuning, model adaptation and multi-agent orchestration T3. Techniques for Evaluation (RQ2) 3.1 Evaluation designs: benchmarks, case studies, expert judgement, experiments 3.2 Metrics and quality criteria used to judge generated architectures 3.3 Cost, latency and reproducibility of the reported setups T4. Emerging Trends (RQ3) 4.1 From single-prompt assistance towards agentic and multi-agent architecting 4.2 Integration with model-driven engineering and formal artefact generation 4.3 Human-AI collaboration and the changing role of the architect 4.4 Movement from design-time assistance towards runtime and continuous architecting 4.5 Trust, governance and responsible adoption in industrial settings T5. Limitations (RQ3) 5.1 Reported limitations in practice 5.2 Reported reliability problems: hallucination, inconsistency, non-determinism T6. Challenges (RQ3) 6.1 Open challenges and stated future work
B10: A Note Related to RQ3 | C10: The trends are not visible on a single piece of paper, as a technique, and therefore each row T4 and under 6.1 represents how the trend was demonstrated. The strongest possible signal is explicit, the authors themselves indicate a change, open challenge or future direction. No signals indicates that they do not. In T1, T 2; T 3 and T 5, there is no signal in the rows. Another value, judgement about the synthesis across studies, and not a property of individual row, was a distributional reading, the spread of the publication years, and is not used (an inferred value in the first pass).
B11: RQ4: The Extension Analysis | C11: In 'SAS extension' sheet, RQ4 is answered. It is not done by coding of the primary studies. Primary studies are about large language models (LLMs) for software architecture design support in general but they are not about self adaptive software systems (SASS). Every sub-theme that is developed based on RQ1 to RQ3 is carried forward and its analysis is done based on the requirements of SASS. Details about our idea of extension of studies towards SASS is also given in 'StudyWise_SAS_Extension'. An answer is not pegged on MAPE-K alone but each study is read off against MAPE-K, Rainbow, and Models@run.time, and on one side a model or the other. According to study: The locus of the architecture object; that breaks down to a SASS, to be expressed as a named property; reading framework with link grade; the best fit and why others do not fit. Where applicable, other models are also suggested in support; for instance self-management systems, as the references are given: - MAPE-K feedback loop: Kephart, J.O. & Chess, D.M. (2003). The Vision of Autonomic Computing. Computer, 36(1), 41-50. DOI 10.1109/MC.2003.1160055 - Rainbow (architecture-based self-adaptation): Garlan, D., Cheng, S.-W., Huang, A.-C., Schmerl, B. & Steenkiste, P. (2004). Rainbow: Architecture-Based Self-Adaptation with Reusable Infrastructure. Computer, 37(10), 46-54. DOI 10.1109/MC.2004.175 - Models@run.time: Blair, G., Bencomo, N. & France, R.B. (2009). Models@run.time. Computer, 42(10), 22-27. DOI 10.1109/MC.2009.326 - Three-layer architecture for self-managed systems: Kramer, J. & Magee, J. (2007). Self-Managed Systems: an Architectural Challenge. Future of Software Engineering (FOSE ’07), 259-268. DOI 10.1109/FOSE.2007.19 - FORMS reference model: Weyns, D., Malek, S. & Andersson, J. (2012). FORMS: Unifying Reference Model for Formal Specification of Distributed Self-Adaptive Systems. ACM Transactions on Autonomous and Adaptive Systems, 7(1), 1-61. DOI 10.1145/2168260.2168268 - EUREMA (executable runtime megamodels): Vogel, T. & Giese, H. (2014). Model-Driven Engineering of Self-Adaptive Software with EUREMA. ACM Transactions on Autonomous and Adaptive Systems, 8(4), 1-33. DOI 10.1145/2555612 - ActivFORMS (active formal models): Iftikhar, M.U. & Weyns, D. (2014). ActivFORMS: Active Formal Models for Self-Adaptation. Proceedings of SEAMS 2014, 125-134. DOI 10.1145/2593929.2593944 - Dynamic software product lines: Hallsteinsen, S., Hinchey, M., Park, S. & Schmid, K. (2008). Dynamic Software Product Lines. Computer, 41(4), 93-95. DOI 10.1109/MC.2008.123 - Control-theoretic adaptation: Filieri, A., Maggio, M., et al. (2015). Software Engineering Meets Control Theory. Proceedings of SEAMS 2015, 71-82. DOI 10.1109/SEAMS.2015.12 - Requirements-driven adaptation (awareness requirements): Souza, V.E.S., Lapouchnian, A., Robinson, W.N. & Mylopoulos, J. (2011). Awareness Requirements for Adaptive Systems. Proceedings of SEAMS 2011, 60-69. DOI 10.1145/1988008.1988018
B12: References | C12: 1- Cruzes, D.S. & Dybå, T. (2011), 'Recommended Steps for Thematic Synthesis in Software Engineering', ESEM 2011, 275-284. DOI 10.1109/ESEM.2011.36. Primary method: the five-step thematic synthesis procedure followed here. 2- Braun, V. & Clarke, V. (2006), 'Using thematic analysis in psychology', Qualitative Research in Psychology, 3(2), 77-101. DOI 10.1191/1478088706qp063oa. Source of the six-phase structure used to organise the analytic work. 3- Braun, V. & Clarke, V. (2021), 'One size fits all? What counts as quality practice in (reflexive) thematic analysis?', Qualitative Research in Psychology, 18(3), 328-352.
B13: Validation | C13: The independent coding was conducted by all authors. Each author used a common code book, which was formulated on the pilot studies, to apply to the same studies without referring to the others, and all disagreement on a code, a sub-theme or a row type was discussed and agreed to an assignment to ensure that none of the code was entered randomly. The coded information in the 'Thematic map' is the consensus outcome of such independent work, not the assigning done by one author. It is a coding-reliability practice per software engineering (SE). One such measure to show consistency between authors is a quantitative agreement statistic; another is independent application of a common code book followed by agreement on the coding completed, which is applied here.
... B18: Scope Criterion and its Supporting Rules | C18: The operational test used at full-text reassessment: A model is in scope when a model executes or in a proposal paper is said to execute a task the object of which is a software architecture. The borderline cases were decided by four supporting rules which are mentioned below since it is on them that the reasons used on the Withdrawn studies sheet are based. (1) The scope is determined by the object of the work of the model: its position within a system is irrelevant. The model as a part of an architecture is not in itself architectural work, and the run-to-run task workflow is not the architecture of the system in which it is instantiated. (2) Metadata can only support a scope decision, and never determines one. Title, keywords, venue and classification terms have only supporting evidence the entire text has the final say. (3) The knowledge-artefact rule. A model that generates a knowledge artefact, e.g. a domain ontology, a knowledge graph or a taxonomy of an application domain, is not performing architectural work. This is not a software architecture but domain knowledge.

Sheet Included_Studies
A1: Sr | B1: ID | C1: Authors | D1: Title | E1: Year | F1: Venue | G1: Contribution type | H1: LLM / Gen AI used | I1: Architectural task addressed | J1: Evaluation type | K1: Family | L1: Coverage and independence
A2: 1 | B2: S1 | C2: Maranhão & Guerra | D2: A Prompt Pattern Sequence Approach to Apply Generative AI in Assisting Software Architecture Decision-making | E2: 2024 | F2: EuroPLoP 2024 | G2: Technique and pattern-language contribution; there is no empirical work attached. There are five prompt patterns of architectural decision making (Software Architect Persona, Architectural Project Context, Quality Attribute Question, Technical Premises, Uncertain Requirement Statement), and they are documented in the forms of a lengthy Coplien and have a list of consequences of two sides. At the top of the catalogue, and of the headline of the paper: a fixed five stage process plus a conditional decision flow with an architect evaluate- and refine gate following the application of each pattern applied. Novelty has partiality and is proclaimed: three of the five specialise published patterns of White et al. (Persona, Question Refinement, Fact Check List) and only two proclaim no specialisation. Usefulness is reported as a practitioner appreciation provided in each of the known-uses sections of the patterns being used by the authors. | H2: ChatGPT or GPT. | I2: The support for architectural decision-making is performed along with quality attribute trade-off and uncertainty handling as well. | J2: An illustrative application is used along with two industrial scenarios and one fictional case; qualitative practitioner feedback is also used. However, there is no baseline. | K2: F1 | L2: 37 meaning units (11 / 7 / 5 / 6 / 6 / 2 across themes T1 to T6). Introduces five patterns; S2 says that there is no assessment of these five patterns in this paper. Shared links are executed transcripts.
A3: 2 | B3: S2 | C3: Maranhão Junior, Melegati & Guerra | D3: Applying a Prompt Pattern Sequence for Decision-Making in Microservices Architectures | E3: 2025 | F3: ESOCC 2025, LNCS 15547, pp. 18-32 | G3: Empirical study, retrospective multi-case (2 cases, 2 participants), assessing patterns shown in S1. The 5 patterns are described again in the paper (both is a contribution and also an evaluation), therefore it constitutes both a re-presentation and an evaluation. | H3: GPT-4o. | I3: The support for architectural decision making is done especially for microservices architectures. | J3: Case study is used, 2 industrial decisions completed that were re-enacted, semi-structured interviews with 2 architects who made the decisions | K3: F1 | L3: 32 meaning units (9 / 5 / 7 / 5 / 5 / 1 across themes T1 to T6). Not independent of S1: 5 patterns, same two Brazilian companies (car financing; 3000 store pharmacy retail), and both published prompt transcript URLs are same as 2 of S1's. Count as one family with S1 when reporting coverage.
A4: 3 | B4: S3 | C4: Diaz-Pace, Tommasel, Capilla & Ramírez | D4: Architecture Exploration and Reflection meet LLM-based Agents | E4: 2025 | F4: ICSA-C 2025 | G4: Agent architecture + Proof of Concept (PoC), and Technique. | H4: GPT-4o-mini, via LlamaIndex. | I4: The study performs exploration for architecture alternatives, tactic and pattern search along with assesment and decision support. | J4: Evaluation involved initial evaluation and a case study published earlier, which was reused (13 requirements); two different agent configurations were evaluated against the original published one; no human subjects were involved. | K4: F2 | L4: 29 meaning units (8 / 4 / 6 / 6 / 4 / 1 across themes T1 to T6). Independent of F1. First study in the corpus to fill sub-themes 1.1, 1.4, 2.3 and 3.2.
A5: 4 | B5: S4 | C5: Dhar, Vaidhyanathan & Varma | D5: Can LLMs Generate Architectural Design Decisions? An Exploratory Empirical Study | E5: 2024 | F5: ICSA 2024 | G5: A comparison in a controlled way is given for three adaptation approaches, Empirical study. | H5: 18 models are used: GPT-2/3/3.5/4 families and T5, T0, Flan-T5 families. | I5: The generation of decision for an architecture decision record from its existing context is done; means architecture knowledge management (AKM). | J5: This is an experiment that is replicated across multiple public repositories (95 records), is compared to an automatic metric of the experiment, and is also manually evaluated on a subset. | K5: F3 | L5: 34 meaning units (7 / 7 / 9 / 6 / 3 / 2 across themes T1 to T6). Not dependent on F1 and F2.
A6: 5 | B6: S5 | C6: Soliman & Keim | D6: Do Large Language Models Contain Software Architectural Knowledge? An Exploratory Case Study with GPT | E6: 2025 | F6: ICSA 2025 | G6: Empirical study, evaluation of embedded knowledge. | H6: GPT-3.5 is used and is stated as the most trending and stable version at the time, as is called via API. | I6: Discussing the architectural knowledge of an existing system: components and connectors, quality-attribute solutions, rationale. | J6: Exploratory single-embedded case study, with 14 engineers, 236 questions, precision/recall/F1 measures, and a manually created ground truth, along with Likert quality and trustworthiness ratings, and a content analysis of the justifications given. | K6: F4 | L6: 36 meaning units (9 / 4 / 8 / 6 / 7 / 2 across themes T1 to T6). Independent of F1-F3. First time of study in the corpus that employs a distinction between trustworthiness and accuracy, (a) constructs a ground truth for an existing system, (b) quantifies the uncertainty in model output, and (c) calls model output randomness as a threat to validity.
A7: 6 | B7: S6 | C7: Ramachandran | D7: Empowering Software Architects with Artificial Intelligence: Analyzing GitHub Copilot's Role in Modern Architecture Design | E7: 2025 | F7: CSECS 2025 | G7: Empirical generation-and-comparison study, single author, practitioner authored, no research design is named, no research question and no threats-to-validity section. A few note-takes are created to build the model manually, then scored by copilot against the four sets of UML diagrams, generated by the same copilot from the requirements specification, that have been published, using a borrowed similarity score in the graph where both the nodes and edges take equal weight, then taken a few adjustments to meet a fixed threshold of 0.6, giving a score of use case 0.56 (which was adjusted up to 0.61), class 0.61, sequence 0.66, and state 0.70. The important part is the deviation annotation per-diagram, with the named annotation omissions and relabellings plus correct material the model generated, which the metric penalises, and a public catalog of prompts; generated markups and scores. | H7: GitHub Copilot and attributes output to ChatGPT. | I7: Creating UML design diagrams (use case, class, sequence, state) from requirements specification. | J7: One reference document is used along with four diagrams, there is one rater, no section for threats-to-validity, no baselines, and no repeatition of experiments. | K7: F5 | L7: 28 meaning units (8 / 3 / 6 / 6 / 3 / 2 across themes T1 to T6). Independent family F5. Co-writes with S19. Second family to reach sub-themes 1.1 and 3.2, so they are no longer single-family. Use its numerical results as an approximation: the stopping rule sets the scores just below 0.6.
A8: 7 | B8: S7 | C8: Eisenreich, Speth & Wagner | D8: From Requirements to Architecture: An AI-Based Journey to Semi-Automatically Generate Software Architectures | E8: 2024 | F8: Designing '24, IEEE/ACM International Workshop on Designing Software | G8: A six-step process is proposed. A vision paper in which one small exploratory test is performed of its first step only. | H8: Currently testing Llama2-70B and GPT-3.5 (chat versions) and considering Llama, Falcon, and Yi for full proposed pipeline, not have been used yet. | I8: Comprehensive pipeline: from requirements to the domain model to multiple architecture candidates to automated evaluation to human selection. | J8: No metric or rater, narrative observation, informal exploratory test of domain-model generation only (91 requirements, MobSTr dataset). Proposal of the stages of architecture generation and evaluation, which have not been tested. Two full studies were planned, but not carried out. | K8: F6 | L8: 26 meaning units (8 / 4 / 4 / 5 / 3 / 2 across themes T1 to T6). Independent (F6). All pipeline-level claims—architecture candidate quality, usefulness of ADR, automation of evaluation; are proposed, not demonstrated, with the domain-model claim being the only one with any sort of empirical support, and the support is informal.
A9: 8 | B9: S8 | C9: Díaz-Pace, Tommasel & Capilla | D9: Helping Novice Architects to Make Quality Design Decisions Using an LLM-Based Assistant | E9: 2024 | F9: ECSA 2024 | G9: Technique and an initial evaluation is performed, ArchMind (a multi-copilot assistant) is used, and its described as an experiment by the authors. | H9: OpenAI GPT-3.5 is used, via Chroma vector store and a Langchain. | I9: Creating architecture decision records for specific requirements: pattern suggestion, decision evaluation, consistency checking, ADR generation | J9: One student project is used as a single system, generated 16 records, five of them were reviewed manually by the authors themselves against the student formed records that were not treated as ground truth. | K9: F2 | L9: 31 meaning units (9 / 5 / 5 / 6 / 4 / 2 across themes T1 to T6). Family member of S3 (F2).
A10: 9 | B10: S9 | C10: Dhar, Vaidhyanathan & Varma | D10: Leveraging Generative AI for Architecture Knowledge Management | E10: 2024 | F10: ICSA-C 2024 | G10: Proposed vision and approach with nothing constructed and nothing assessed. In two steps, proposes using a multi-modal retrieval-augmented generation for a system that can retrieve AK from a project's own repositories, import it from other sources, check the correctness of query results with an Oracle verifier and store the results with an AK generator; and for a retrieval phase that returns the result to open-ended and/or template questions that are appropriate to the question poser's role. Four engineering challenges the system would need to overcome are stated in the motivation section. The paper contains no empirical claims in it other than a rewritten summary of the own exploratory study of creating architecture decision records (this corpus contains the complete original study as S4). | H10: T5 based model family and GPT; the proposed fusion/extraction/ or retrieval pipeline itself uses no named model, being unbuilt. | I10: The entire AKM lifecycle: Extracting AK from a system, combining it with external knowledge, validating it and answering stakeholder questions against it. | J10: It is an empirical section that summarizes S4's exploratory study (same models, metrics, GitHub repository, and conclusions), but does not include any extraction, fusion, verification and retrieval components, nor is there any implementation or evaluation of those components. | K10: F3 | L10: 29 meaning units (9 / 5 / 3 / 7 / 3 / 2 across themes T1 to T6). Same family as S4 (F3): all three authors are the same, and S4's reference list mentions that this is 'companion work'.
A11: 10 | B11: S10 | C11: Jahić & Sami | D11: State of Practice: LLMs in Software Engineering and Software Architecture | E11: 2024 | F11: ICSA-C 2024 | G11: It is an empirical study of mixed methods, containing experiments on zero-shot generation with an industrial survey that is used for validation. | H11: For reproducibility; GPT 3.5 has been chosen over GPT-4, both are tried and compared. | I11: Creating C4-model based views (System Context, Container, Component) and tool-chain suggestion based on requirements description | J11: 50 experiments in 5 real projects, manually analyzed and blindly reviewed with 4 original project authors as reviewers; industry survey of 15 companies as a validation. | K11: F7 | L11: 35 meaning units (10 / 4 / 6 / 8 / 5 / 2) for themes T1 to T6.
A12: 11 | B12: S11 | C12: Ahmad, Waseem, Liang, Fahmideh, Aktar & Mikkonen | D12: Towards Human-Bot Collaborative Software Architecting with ChatGPT | E12: 2023 | F12: Ease 2023 | G12: Three activities human-bot cooperative architecting process with example “process proposal + illustrative case study.” The authors characterize the results as preliminary and explicitly set the empirical results from the third phase out of the scope of the study. | H12: ChatGPT (date of use and the settings of version are not stated anywhere in the article). | I12: The complete architecting process, which involves architecturally significant requirements elicitation from an architecture story, architecturally significant UML class and component models (architectural synthesis), and architecturally significant scenarios (SAAM) | J12: One case study of a campus bike-sharing application was used as an exemplifying case study; one architect, no other participants, no baseline, no metric, no repetition. S6 will not be able to analyse threats to validity as it has them under internal, external and conclusion validity. | K12: F8 | L12: 32 meaning units (10 / 4 / 5 / 8 / 3 / 2) for themes T1 to T6.
A13: 12 | B13: S12 | C13: Keim, Kaplan, Koziolek & Mirakhorli | D13: Does BERT Understand Code?, An Exploratory Study on the Detection of Architectural Tactics in Code | E13: 2020 | F13: ECSA 2020 | G13: Empirical study and technique (BERT fine-tuned as a multi-class code classifier) with comparative evaluation against 7 prior ML baselines. | H13: BERT-base, fine-tuned with transfer learning (TL) for classification. | I13: Architecture analysis/recovery: Identification of the architectural tactics implemented by an existing code class (of a predefined set of five) to facilitate recovery of the traceability link from the code back to the quality-driven design decisions. | J13: 10-fold cross-validation of a reused dataset (Mirakhorli et al. 2016) + replication on Apache Hadoop HDFS; benchmarked against 7 other classifiers: SVM, Slipper, J48, Bagging, AdaBoost, Bayesian, Mirakhorli's Tactic Detector; evaluated using Precision/Recall/F1; Friedman significance test for classifiers. | K13: F9 | L13: 29 meaning units (8 / 5 / 4 / 5 / 6 / 1) around themes T1 to T6.
... A24: 23 | B24: S23 | C24: Jafari Sarvejahani | D24: Towards Architectural Pen Test Case Generation and Attack Surface Analysis to Support Secure Design | E24: 2025 | F24: ICSA-C 2025 | G24: States three research questions and some initial ideas on how to derive penetration test cases from architectural models, how to prioritise the test cases based on their severeness and how to score alternative architectures based on attack-surface complexity, which in turn can be used as inputs to a recommender for the architects. The paper is about work that is proposed not work that has been done. | H24: It is one of three proposed strategies, and the plan will be to first develop a non-model algorithm (over public weaknesses, attack-pattern and vulnerability collections) and, only after the development of the non-model algorithm, consider whether a model can be used to replace parts of the algorithm, or enhance parts of the algorithm; the algorithm to be used as a baseline. | I24: The whole point of it is that it aids architectural design - that is, it takes architectural models as input, returns secure design decisions as output, and the architect is the intended user. The model is also placed at the analysis end of design support, which is the first time in the corpus that it was done instead of the generation end: The architecture is evaluated and rated for architects. | J24: An evaluation strategy is expressed, but no evaluation has been performed for the self-built algorithm (non-model) or against comparable published algorithms in the autonomous-vehicle domain, for accuracy, precision, recall and effectiveness. | K24: F18 | L24: 36 meaning units (10 / 6 / 7 / 8 / 3 / 2) for themes T1 to T6.

Sheet Withdrawn_Studies
A1: Original Corpus ID | B1: Authors | C1: Full title | D1: Year | E1: Family | F1: Units withdrawn | G1: Reason for Exclusion
A2: S10 | B2: Shethiya | C2: LLM-Powered Architectures: Designing the Next Generation of Intelligent Software Systems | D2: 2023 | E2: F17 | F2: 8 | G2: The contribution is an architectural knowledge of a class of LLM based systems and no model carries out any architectural task. It was determined that second limb of criterion "architecture for LLM-based systems" was not considered and adopted, thus the system was withdrawn. This is a scope decision and not a quality judgement. A study without narration, system, case run and evaluation. It outlines architectural patterns to apply LLM in software systems (like RAG, Prompt Chain, Agent Orchestration, Synchronous and Asynchronous Pipelines) and presents a generic reference diagram and governance framework including scope of the model, prompt auditing, bias mitigation, privacy and lifecycle management, all authored by the author. There were 2 scope independent source verified quality defects. No reference to the text: 11 citations, but none of these to the claim they support. The stated issue date is April 2023, which doesn't match the text which says model input limits are 8K to 128K tokens.
A3: S16 | B3: Smirnov, Levashova & Ponomarev | C3: Decision Support Based on Large Language Models: Ontology-based Architecture and Generalized Scenario | D3: 2026 | E3: F12 | F3: 23 | G3: No model does any architectural task, the contribution is architectural knowledge of a class of LLM-based systems. The second limb of criterion for architecture for LLM based systems was discussed but not included. This is a scope decision as opposed to a quality decision, as there are a number of sources in Group C that are the best in the list of candidates and most rich in RQ4. Architectural designs are the work of the human authors; no model does architectural work, all four workflows are designed by the human authors. The one positive row at 1.1 is a modelling of an application domain conceptually (that is, a domain ontology, not software-architecture work) as opposed to the modelling of software-architectures made by S54. During this phase, conceptual models are developed which are not tested empirically, according to the paper. Counted as an external anchor reference for RQ4 and not in total count.
A4: S17 | B4: Santhosh, Baskar & Janani | C4: Intelligent Multi-Agent Architecture Leveraging Large Language Models for Transparent, Interactive Financial Analysis and Strategic Investment Recommendation | D4: 2026 | E4: F13 | F4: 29 | G4: In the financial analysis, application paper. The task object of the model is not a software architecture, but a financial analysis, and a recommendation on investment. There is no architectural task and no architectural contribution in 1.1-1.4, because all the rows are negative in this range.
A5: S18 | B5: Guo, Guo, Li, Huang, Zhu & Zou | C5: Disturbance-Aware Closed-Loop Rescheduling for Airport Ground Operations via LLM-Enhanced Decision Support | D5: 2026 | E5: F14 | F5: 28 | G5: Application paper for the airport ground service. The model's task object is not a software architecture, but a modified schedule for performing the ground operations. There is no positive row in each of 1.1 – 1.4 so there is no architectural task, and no architectural contribution.
A6: S19 | B6: Park, Park & Kim | C6: WildfireKR: An LLM-Agent Decision Support Framework for Autonomous Wildfire Spread Simulation in South Korea | D6: 2026 | E6: F15 | F6: 32 | G6: Application paper: for emergency and environmental modelling. The task object of the model is not the software architecture, but a simulation of the spread of wild fires. There are no positive rows at any of 1.1-1.4 so there is no architectural task and no architectural contribution.
A7: S22 | B7: Sarao | C7: Next-Gen AI Decision Support in Software Engineering: Leveraging Complexity with Quantum Computing, DevOps Automation, and Responsible Machine Learning | D7: 2025 | E7: F19 | F7: 26 | G7: A positive row at position 1.3 (where one application was designed by the authors), however this row is not associated with any architectural work by any model. In such a paper, if the design extends to other contexts and becomes a basis for creating a transferable set of guidance, then this guidance is the result of the building of the system and is not the contribution of that paper.
A8: S23 | B8: Narsepalle, Bolla & Bandaru | C8: A Cloud-Native Generative AI Agent Architecture for Predictive Cardiovascular Health Analytics | D8: 2026 | E8: F20 | F8: 25 | G8: Application paper, a clinical analytical application. The task object for the model is a cardiovascular risk analysis and not a software architecture. There is no architectural task (and no architectural contribution), since there are no positive rows at any of 1.1-1.4.
A9: S24 | B9: Li, Zhang, Zhang, Zhou, Bai, Li, Gu, Li, Du, Li, Chen & Wu | C9: Large Language Model Driven Auxiliary Decision System for Substation Equipment Status Assessment and Technical Retrofit | D9: 2025 | E9: F21 | F9: 25 | G9: Application paper, a clinical analytical application. The task object for the model is a cardiovascular risk analysis and not a software architecture. There is no architectural task (and no architectural contribution), since there are no positive rows at any of 1.1-1.4.
A10: S25 | B10: Lu, Zhu, Xu, Liu, Xing & Whittle | C10: A Taxonomy of Foundation Model based Systems through the Lens of Software Architecture | D10: 2024 | E10: F22 | F10: 38 | G10: The contribution is the knowledge of the architecture of a class of LLM based systems, with no model doing any architectural work. Not adopted due to the second criterion; architecture for LLM based systems, which was considered. None of the models are actually run, the paper itself is a systematic literature review and the result is a classification. All the six positive rows at 1.2 and 1.3 are authors' own catalogue or proposals such as architecture options catalogued, deployment options catalogued along 3 dimensions, an AI bill of materials, a co-versioning registry and standardised reporting. It is on the same area of land as S31, and withdrawn for the same reason. The total will not include counting which will be used as an anchor for RQ4.
A11: S26 | B11: Kumar, Sagar & Jain | C11: Autonomous Multi Agent Collaborators for Enterprise Decision Support: An Agentic AI Framework to Hybrid RAG and Text-to-SQL | D11: 2026 | E11: F23 | F11: 28 | G11: Paper to be used in Enterprise Analytics. The model doesn't represent a software architecture, but rather a business question that is answered by the hybrid retrieval and text-to-SQL model. The row at each of 1.1-1.4 is negative, there is no architectural task and no architectural contribution.
A12: S27 | B12: Becattini, Verdecchia & Vicario | C12: An Accountability-Based Architectural Tactic for Agent Cooperation in LLM-Based Multi-Agent Systems | D12: 2025 | E12: F24 | F12: 33 | G12: No model doing any architectural action, no contribution is an architectural knowledge of a class of systems based on LLM. The second part of the criterion (architecture for LLM-based systems) was taken into account and not adopted. The authors' architecture builds on their own previous architecture and is designed based on the architectural tactic, agent types, relationship types, operating scope, knowledge split and operating layer split. The reported architectural choices of the agents do not contain any output; all architectural constraints in this case study are human Authored (not human chosen) constraints.
A13: S28 | B13: Wu, Guo, Luo & Zhou | C13: Zero-Shot Autonomous Dialogue Agent for Efficient Electric Power Data Inquiry | D13: 2025 | E13: F25 | F13: 27 | G13: Form to be filled out to gain access to a set of data. The task object and response of the model is in natural language (data query) instead of software architecture. There is no architectural task and no architectural contribution for any positive row at any of 1.1-1.4.
... A36: S58 | B36: Klot, Dordevic, Tsaramirsis & Nassereddine | C36: Goal-Based Multi-Agent AI Systems for Academic Advising: A Survey of Policies, Risk Detection, and Intervention Frameworks | D36: 2026 | E36: F51 | F36: 9 | G36: No Model used and no evaluation reported. Architecture content is the property of the authors. They present in Section VI an Academic Multi-Agent Advising System (AMAS), which they describe as a multi-agent, goal-driven and governance-aware system. It consists of five agents: a Student Context Agent that maintains the context of the student, a Risk Detection Agent that predicts risk of course failure, probation or dropout, a Policy and Compliance Agent that compares recommendations to prerequisites, credit limits and probation rules, a Goal and Planning Agent that creates multi-semester plans, and an Intervention Agent that identifies nudges, advisor alerts, referrals and timetable adjustments. Taxonomy is appended to the Table II, which categorizes the advising systems based on goals representation, planning horizon, risk awareness, autonomy in intervention and governance. Two reasons were given for excluding the paper. First, all agents play a part in the tasks of academic advising, or student risk, progression plans and interventions and not a software architecture. No architectural task is performed by any model and no model is specified to perform an architectural task. Second, the architecture and the taxonomy are architectural knowledge about a class of AI-based systems, authored by the researchers.

Sheet Thematic_Map
A1: Study | B1: Year | C1: Meaning unit | D1: Code | E1: Sub-theme | F1: Theme | G1: Trend signal | H1: Source | I1: Row type | J1: Approach/Type
A2: S2 | B2: 2025 | C2: What is being exercised here is the "decision" that was made about already existing microservices architectures, e.g. the two retrospective cases replay decisions that have been made and compare the answers of the model with what was actually implemented. | D2: Decision support assessed on the created systems, not on the generation of the architecture. | E2: 1.1 Architecture generation and synthesis from requirements | F2: T1. LLMs Application / Usage for Architecture Design | H2: Section 1, Section 2, Section 3 | I2: Related activity | J2: T1: design production (1.1-1.3)
A3: S1 | B3: 2024 | C3: The approach is applicable to an architecture that the architect is designing. The pattern of the persona instructs the model to concentrate on named qualities, the pattern of the question is to question the architect before giving answers, and what returns is suggestions with justifications. | D3: No suggestions generated in a decision dialogue. | E3: 1.1 Architecture generation and synthesis from requirements | F3: T1. LLMs Application / Usage for Architecture Design | H3: Section 3-Section 7, Known Uses | I3: Related activity | J3: T1: design production (1.1-1.3)
A4: S3 | B4: 2025 | C4: A textual requirement is given with a short description of the corresponding system and the design agents generate design solutions independently from one another, with the result of each agent trajectory being a solution, and the results being summarised, ranked and presented to the user. | D4: Agent produces ranked design solutions from text requirements. | E4: 1.1 Architecture generation and synthesis from requirements | F4: T1. LLMs Application / Usage for Architecture Design | H4: Section III, Figure 3 | I4: Evidenced | J4: T1: design production (1.1-1.3)
A5: S5 | B5: 2025 | C5: The study is asking what the model already knows about an existing system in terms of the architecture and comparing it to a ground truth. Nothing here produces an architecture, it is a general capacity of language models to show up in the introduction and as other people's work in related work. | D5: If there is information in the model, it is recalled and nothing is created. | E5: 1.1 Architecture generation and synthesis from requirements | F5: T1. LLMs Application / Usage for Architecture Design | H5: Section I, Section II | I5: Related activity | J5: T1: design production (1.1-1.3)
A6: S4 | B6: 2024 | C6: The generation task is the Decision of an architecture decision record that was created from the Context of that record. | D6: The object produced is a decision field, and not an architecture. | E6: 1.1 Architecture generation and synthesis from requirements | F6: T1. LLMs Application / Usage for Architecture Design | H6: Section I, Section III | I6: Related activity | J6: T1: design production (1.1-1.3)
A7: S6 | B7: 2025 | C7: From a requirements specification, a set of four UML design diagram types (use case, class, sequence and state) are generated, and the output is requested to be in a textual diagram-markup format, which can be used to render the design diagrams by standard diagramming tools. | D7: A collection of four UML diagram types that have been created from a requirements document. | E7: 1.1 Architecture generation and synthesis from requirements | F7: T1. LLMs Application / Usage for Architecture Design | H7: Section I, Section VII, Section VIII | I7: Evidenced | J7: T1: design production (1.1-1.3)
A8: S6 | B8: 2025 | C8: The requirements were pre-processed before prompting, where the functionality of the product and its requirements in the specification were summarised into functional categories and the content of these were used as the prompt. Neither is it a step spelled out in an imperative nor is it a step that is attributed to a person. | D8: Requirements summarized into functional categories and not prompted. | E8: 1.1 Architecture generation and synthesis from requirements | F8: T1. LLMs Application / Usage for Architecture Design | H8: Section VII, Table II | I8: Evidenced | J8: T1: design production (1.1-1.3)
A9: S6 | B9: 2025 | C9: All four produced the same type of diagrams which were the same as the reference, with reported similarity scores of 0.61 for use case, 0.61 for class, 0.66 for sequence and 0.7 for state. | D9: Partial match for any of the four diagram types | E9: 1.1 Architecture generation and synthesis from requirements | F9: T1. LLMs Application / Usage for Architecture Design | H9: Section X, Table III | I9: Evidenced | J9: T1: design production (1.1-1.3)
A10: S7 | B10: 2024 | C10: A proposed process is six steps: generate a domain model from the textual requirements and automatically generate use-case scenarios, manually edit both of these, automatically generate multiple architecture candidates and design decisions, automatically assess the candidates, manually edit the candidates, and then manually select the best fit. | D10: Requirements to selected architecture pipeline is shown as a 6-step process. The 6-step pipeline from requirements to selected architecture is demonstrated. | E10: 1.1 Architecture generation and synthesis from requirements | F10: T1. LLMs Application / Usage for Architecture Design | H10: Section 3, Figure 1 | I10: Evidenced | J10: T1: design production (1.1-1.3)
A11: S7 | B11: 2024 | C11: The authors contrast this with Kof's previous semi-automatic domain model generation, which demanded significant manual work to draft the requirements documents, and conclude that recently developed LLMs can significantly decrease that manual work. | D11: Located as the answer to manual effort compared to previous semi-automatic tasks | E11: 1.1 Architecture generation and synthesis from requirements | F11: T1. LLMs Application / Usage for Architecture Design | H11: Section 1, Section 2 | I11: Evidenced | J11: T1: design production (1.1-1.3)
A12: S8 | B12: 2024 | C12: The end-to-end scenarios are scenarios that are selected and passed through the copilot pipeline and the output is a set of sixteen architecture decision records. | D12: Requirements should be passed down to decision records, not an architecture. | E12: 1.1 Architecture generation and synthesis from requirements | F12: T1. LLMs Application / Usage for Architecture Design | H12: Section 3.1, Section 4 | I12: Related activity | J12: T1: design production (1.1-1.3)
A13: S9 | B13: 2024 | C13: One of six proposed query templates, Candidate Architecture, is designed to create a candidate architecture for a new system that is similar to an existing, documented one, but is not meant to be used to extract knowledge about a documented system. | D13: One type of query template suggests generating candidate architectures for new systems | E13: 1.1 Architecture generation and synthesis from requirements | F13: T1. LLMs Application / Usage for Architecture Design | H13: Section IV-B | I13: Evidenced | J13: T1: design production (1.1-1.3)
... A495: S16 | B495: 2025 | C495: Absence: No model is specified and no cost, latency, or configuration value is provided anywhere in the entire paper, or indeed anywhere in the three case studies. The generative model is described as an LLM agent consistently in the paper, but no model, version, provider, temperature, context setting, token count, cost, or call count appears anywhere in the paper, nor in the three case studies. The single piece of cost-related information provided in the paper is explicitly qualitative and not quantitative, the caption noting that the trendlines shown do not provide actual quantitative values. | D495: Absence: No model named and no cost, latency or reproducibility figure is found anywhere. | E495: 3.3 Cost, latency and reproducibility of the reported setups | F495: T3. Techniques for Evaluation | H495: Sections IV-B, V, VI-B, Figure 10 caption; would have appeared in Section V | I495: Coded silence | J495: T3: evaluation technique
A497: S1 | B497: 2024 | C497: The contribution lies in a chain of prompting with conditional branches and an evaluation gate following each prompt, instead of a single prompt. | D497: Multi-step conditional chain is an alternative to single-prompt use. | E497: 4.1 From single-prompt assistance towards agentic and multi-agent architecting | F497: T4. Emerging Trends | G497: No signal | H497: Section 8, Section 8.1 | I497: Evidenced | J497: T4: emerging trend
A498: S2 | B498: 2025 | C498: The two architects independently request that the fixed sequence be changed to an interactive dialogue with further questions and the authors agree in their future work with respect to this, suggesting a departure from the idea of a fixed prompt sequence. | D498: Fixed sequence moved in direction of interactive dialogue | E498: 4.1 From single-prompt assistance towards agentic and multi-agent architecting | F498: T4. Emerging Trends | G498: Explicit | H498: Section 5, Section 6 | I498: Evidenced | J498: T4: emerging trend
A499: S3 | B499: 2025 | C499: The framework used by the authors is that current architectural work is based on fixed-model prompting and is lagging behind code agents, and that architectural tools need to be transformed into design agents which will have autonomy and tool usage, multiple agents working together to address different needs being mentioned as the next step. | D499: Stand alone prompting replaced by design agents | E499: 4.1 From single-prompt assistance towards agentic and multi-agent architecting | F499: T4. Emerging Trends | G499: Explicit | H499: Section I, Section V, Section VI | I499: Evidenced | J499: T4: emerging trend
A500: S6 | B500: 2025 | C500: Absence: A single assistant takes care of prompts in an editor. There is no mention of any agent, orchestration or delegation. | D500: Absence: An absence of agency, multi-agency direction | E500: 4.1 From single-prompt assistance towards agentic and multi-agent architecting | F500: T4. Emerging Trends | G500: No signal | H500: whole paper | I500: Coded silence | J500: T4: emerging trend
A501: S5 | B501: 2025 | C501: Absence: the study invokes one model through an API. There is no mention of an agent, tool use, delegation or orchestration in either the study or the directions the authors lay out. | D501: Absence: No control or agency by one or more agents | E501: 4.1 From single-prompt assistance towards agentic and multi-agent architecting | F501: T4. Emerging Trends | G501: No signal | H501: whole paper | I501: Coded silence | J501: T4: emerging trend
A502: S4 | B502: 2024 | C502: Absence: all configurations consist of a single model invocation per record. There is no mention of an agent, tool use, orchestration or delegation in either the study or the directions the authors indicate their work is heading toward. | D502: Absence: No agentic or multi-agent direction | E502: 4.1 From single-prompt assistance towards agentic and multi-agent architecting | F502: T4. Emerging Trends | G502: No signal | H502: whole paper | I502: Coded silence | J502: T4: emerging trend
A503: S7 | B503: 2024 | C503: It is proposed that the proposed process explicitly alternates automatic generation and manual refinement over three stages (the domain model, architecture candidates and final selection) instead of generating an architecture from one invocation. | D503: Three stages of explicitly interleaved generation and human refinement. | E503: 4.1 From single-prompt assistance towards agentic and multi-agent architecting | F503: T4. Emerging Trends | G503: Explicit | H503: Section 3, Figure 1 | I503: Evidenced | J503: T4: emerging trend
A504: S8 | B504: 2024 | C504: The pipeline consists of a four-step protocol with task-specialized copilots, optionally with a question-and-answer task, conducted by a senior architect who can intervene at certain points to provide input or refine output. This is a set process instead of agents which can plan and delegate, and the authors describe the tool as experimental and not heading toward autonomy. | D504: A human intervention points-based fixed task pipeline, not Autonomous agents | E504: 4.1 From single-prompt assistance towards agentic and multi-agent architecting | F504: T4. Emerging Trends | G504: Explicit | H504: Section 3.1, Section 3.3 | I504: Related activity | J504: T4: emerging trend
A505: S9 | B505: 2024 | C505: Unlike the generative approach taken by the existing systems, the suggested system is built around the concept of two chained processes - extraction and retrieval, with the former broken down into four separate sub-processes executed by different components. | D505: The whole system was carefully broken into sequential multi-step process.The overall system was carefully divided into cascaded multi-step processes. | E505: 4.1 From single-prompt assistance towards agentic and multi-agent architecting | F505: T4. Emerging Trends | G505: Explicit | H505: Section IV, Figure 1, Figure 2 | I505: Evidenced | J505: T4: emerging trend
A506: S10 | B506: 2024 | C506: Absence: In both controlled experiments and the survey there is no mention of agents, orchestration or delegation; none of those is included in the list of future expectations asked about in a research aimed at recording the existing practices and expectations for the future. | D506: Absence: no agentic or multiple agentic direction | E506: 4.1 From single-prompt assistance towards agentic and multi-agent architecting | F506: T4. Emerging Trends | G506: No signal | H506: whole paper | I506: Coded silence | J506: T4: emerging trend
A507: S11 | B507: 2023 | C507: The collaboration suggested by the authors is based on three separate processes of architecting (analysis, synthesis and evaluation), which have been borrowed from the architecting process, developed on the basis of five industrial approaches, and performed as separate steps of one single dialogue, rather than a generative request. | D507: A process was broken down to three sequential architecting activities. | E507: 4.1 From single-prompt assistance towards agentic and multi-agent architecting | F507: T4. Emerging Trends | G507: Explicit | H507: Section 2.1, Section 2.2, Figure 2, Figure 3 | I507: Evidenced | J507: T4: emerging trend
A508: S11 | B508: 2023 | C508: According to the authors, within the domain of software architecting the application of AI technologies in general and development bots in particular has been reduced only to answering questions or providing recommendations concerning erosion and maintenance of architectures, and there is no research studying the application of these bots in the architecting process. | D508: The authors mention that current bots are limited to the question and answer/Recommendation area. | E508: 4.1 From single-prompt assistance towards agentic and multi-agent architecting | F508: T4. Emerging Trends | G508: Explicit | H508: Section 2.1 | I508: Evidenced | J508: T4: emerging trend
... A670: S23 | B670: 2025 | C670: Absence: lack of governance of the generated artifact: it is unclear who reviews the generated attack scenario by the model before the architect acts on it and what will happen if the rating is incorrect. | D670: Absence: No monitoring or assurance of attack scenarios generated by a model | E670: 4.5 Trust, governance and responsible adoption in industrial settings | F670: T4. Emerging Trends | G670: No signal | H670: whole paper | I670: Coded silence | J670: T4: emerging trend
A671: S3 | B671: 2025 | C671: Limitations of the approach that are identified in the Discussion include three. Some of the recommendations obtained by the agents are not patterns or tactics found in the literature; they are referred to as hallucinations. The recommendations have been identified as being too generic, while coping with both of these problems remains difficult. The value of the approach is stated to depend on its tools being based on the proper architectural knowledge, while the validation of this approach by means of practical experiments and metrics is seen as essential for its improvement. Two additional problems with the run in question – duplication of the patterns that increase the burden of inference and the failure of the tree search agent to use its decision assessment tool – are marked by the codes 3.3 and 5.2 respectively. | D671: Hallucinated options, over-general recommendations and a grounding dependence | E671: 5.1 Reported limitations in practice | F671: T5. Limitations | H671: Section IV, Discussion; Section IV results | I671: Evidenced | J671: T5: limitation
A672: S14 | B672: 2026 | C672: Absence: There is no limitation in practice observed. The article claims that there is a significant F1 improvement over its industrial baseline, and there are significant benefits of dependency context; however, the article does not note any specific conditions, costs, and failures of its approach except for these two. | D672: Absence: (no limitations reported) next to the measured gains | E672: 5.1 Reported limitations in practice | F672: T5. Limitations | H672: whole paper | I672: Coded silence | J672: T5: limitation
A673: S1 | B673: 2024 | C673: Among the drawbacks noted are prolonged planning period, delay of time-sensitive projects, increase in the cognitive load, and scope creep in case multiple quality attributes are targeted at the same time. | D673: Structured prompting slows and complicates decision process. | E673: 5.1 Reported limitations in practice | F673: T5. Limitations | H673: Section 5, Section 6 Consequences | I673: Evidenced | J673: T5: limitation
A674: S1 | B674: 2024 | C674: The persona is noted to potentially introduce unintentional bias and to limit response flexibility in case the constraints are defined too strictly. | D674: Over-constrained persona presents bias and rigidity. | E674: 5.1 Reported limitations in practice | F674: T5. Limitations | H674: Section 3 | I674: Evidenced | J674: T5: limitation
A675: S1 | B675: 2024 | C675: The Architectural Project Context pattern demonstrated low flexibility under different project contexts, especially in case of pharmacy retail domain, and possibly requires removal of its variables. | D675: Unfortunately, context transfer is not that good between projects. | E675: 5.1 Reported limitations in practice | F675: T5. Limitations | H675: Section 4 Known Uses | I675: Evidenced | J675: T5: limitation
A676: S2 | B676: 2025 | C676: It was noticed by architects that in some cases, the model would provide general or too broad recommendations failing to provide necessary specificity for highly complex technical environments. Concrete examples were provided by the pharmacy architect who needed the test types to be specified, and also expected the use of Kubernetes for management and scaling. | D676: The suggested resources or tools are not specific enough for complex environments. | E676: 5.1 Reported limitations in practice | F676: T5. Limitations | H676: Section 4.2, Section 5 | I676: Evidenced | J676: T5: limitation
A677: S2 | B677: 2025 | C677: There were two concrete problems noted in the practical use of the model: the recommendation of micro front-ends without prior questioning of the backend configuration, and the underestimation of implementation time compared to the needs of the project. | D677: General failures: lack of focus, unrealistic goals, lack of commitment, lack of drive. | E677: 5.1 Reported limitations in practice | F677: T5. Limitations | H677: Section 4.1, Section 4.2 | I677: Evidenced | J677: T5: limitation
A678: S2 | B678: 2025 | C678: The authors note that results should be interpreted in the context of microservices because of the numerous publications on that topic that helped to train the model and probably explain the correctness of its responses. | D678: Abundant training material seemed to be a part of the reason for good performance. | E678: 5.1 Reported limitations in practice | F678: T5. Limitations | H678: Section 5 Limitations | I678: Evidenced | J678: T5: limitation
A679: S4 | B679: 2024 | C679: All of the three output methods fall short of human-level output; the best 0-shot model provides correct formatting but not the full decision. | D679: Not quite human, but format adherence achieved; decision content Sub-human. | E679: 5.1 Reported limitations in practice | F679: T5. Limitations | H679: Section V-A, Section VI-A | I679: Evidenced | J679: T5: limitation
